2022-12-14 15:07:36,014 INFO werkzeug MainThread : [31m[1mWARNING: This is a development server. Do not use it in a production deployment. Use a production WSGI server instead.[0m
 * Running on http://127.0.0.1:5000
2022-12-14 15:07:36,014 INFO werkzeug MainThread : [33mPress CTRL+C to quit[0m
2022-12-14 15:07:53,707 INFO app Thread-1 (process_request_thread) : All users were selected from database
2022-12-14 15:07:53,708 INFO werkzeug Thread-1 (process_request_thread) : 127.0.0.1 - - [14/Dec/2022 15:07:53] "GET /api/v1/get_all_people_data HTTP/1.1" 200 -
2022-12-14 15:09:10,436 INFO werkzeug MainThread : [31m[1mWARNING: This is a development server. Do not use it in a production deployment. Use a production WSGI server instead.[0m
 * Running on http://127.0.0.1:5000
2022-12-14 15:09:10,436 INFO werkzeug MainThread : [33mPress CTRL+C to quit[0m
2022-12-14 15:09:12,927 INFO app Thread-1 (process_request_thread) : All users were selected from database
2022-12-14 15:09:12,929 INFO werkzeug Thread-1 (process_request_thread) : 127.0.0.1 - - [14/Dec/2022 15:09:12] "GET /api/v1/get_all_people_data HTTP/1.1" 200 -
2022-12-14 15:10:43,191 ERROR app Thread-2 (process_request_thread) : Exception on /api/v1/num_visits [GET]
Traceback (most recent call last):
  File "/home/daniel/Documents/CS/Projects/labs-databases-course/main_project/server/venv/lib/python3.10/site-packages/redis/connection.py", line 598, in connect
    sock = self.retry.call_with_retry(
  File "/home/daniel/Documents/CS/Projects/labs-databases-course/main_project/server/venv/lib/python3.10/site-packages/redis/retry.py", line 46, in call_with_retry
    return do()
  File "/home/daniel/Documents/CS/Projects/labs-databases-course/main_project/server/venv/lib/python3.10/site-packages/redis/connection.py", line 599, in <lambda>
    lambda: self._connect(), lambda error: self.disconnect(error)
  File "/home/daniel/Documents/CS/Projects/labs-databases-course/main_project/server/venv/lib/python3.10/site-packages/redis/connection.py", line 664, in _connect
    raise err
  File "/home/daniel/Documents/CS/Projects/labs-databases-course/main_project/server/venv/lib/python3.10/site-packages/redis/connection.py", line 652, in _connect
    sock.connect(socket_address)
ConnectionRefusedError: [Errno 111] Connection refused

During handling of the above exception, another exception occurred:

Traceback (most recent call last):
  File "/home/daniel/Documents/CS/Projects/labs-databases-course/main_project/server/venv/lib/python3.10/site-packages/flask/app.py", line 2525, in wsgi_app
    response = self.full_dispatch_request()
  File "/home/daniel/Documents/CS/Projects/labs-databases-course/main_project/server/venv/lib/python3.10/site-packages/flask/app.py", line 1822, in full_dispatch_request
    rv = self.handle_user_exception(e)
  File "/home/daniel/Documents/CS/Projects/labs-databases-course/main_project/server/venv/lib/python3.10/site-packages/flask_cors/extension.py", line 165, in wrapped_function
    return cors_after_request(app.make_response(f(*args, **kwargs)))
  File "/home/daniel/Documents/CS/Projects/labs-databases-course/main_project/server/venv/lib/python3.10/site-packages/flask/app.py", line 1820, in full_dispatch_request
    rv = self.dispatch_request()
  File "/home/daniel/Documents/CS/Projects/labs-databases-course/main_project/server/venv/lib/python3.10/site-packages/flask/app.py", line 1796, in dispatch_request
    return self.ensure_sync(self.view_functions[rule.endpoint])(**view_args)
  File "/home/daniel/Documents/CS/Projects/labs-databases-course/main_project/server/app.py", line 24, in num_visits
    count = get_hit_counts()
  File "/home/daniel/Documents/CS/Projects/labs-databases-course/main_project/server/utils.py", line 13, in get_hit_counts
    raise exc
  File "/home/daniel/Documents/CS/Projects/labs-databases-course/main_project/server/utils.py", line 10, in get_hit_counts
    return cache.incr('hits')
  File "/home/daniel/Documents/CS/Projects/labs-databases-course/main_project/server/venv/lib/python3.10/site-packages/redis/commands/core.py", line 1852, in incrby
    return self.execute_command("INCRBY", name, amount)
  File "/home/daniel/Documents/CS/Projects/labs-databases-course/main_project/server/venv/lib/python3.10/site-packages/redis/client.py", line 1255, in execute_command
    conn = self.connection or pool.get_connection(command_name, **options)
  File "/home/daniel/Documents/CS/Projects/labs-databases-course/main_project/server/venv/lib/python3.10/site-packages/redis/connection.py", line 1389, in get_connection
    connection.connect()
  File "/home/daniel/Documents/CS/Projects/labs-databases-course/main_project/server/venv/lib/python3.10/site-packages/redis/connection.py", line 604, in connect
    raise ConnectionError(self._error_message(e))
redis.exceptions.ConnectionError: Error 111 connecting to 127.0.0.1:6379. Connection refused.
2022-12-14 15:10:43,197 INFO werkzeug Thread-2 (process_request_thread) : 127.0.0.1 - - [14/Dec/2022 15:10:43] "[35m[1mGET /api/v1/num_visits HTTP/1.1[0m" 500 -
2022-12-14 15:10:45,703 ERROR app Thread-3 (process_request_thread) : Exception on /api/v1/num_visits [GET]
Traceback (most recent call last):
  File "/home/daniel/Documents/CS/Projects/labs-databases-course/main_project/server/venv/lib/python3.10/site-packages/redis/connection.py", line 598, in connect
    sock = self.retry.call_with_retry(
  File "/home/daniel/Documents/CS/Projects/labs-databases-course/main_project/server/venv/lib/python3.10/site-packages/redis/retry.py", line 46, in call_with_retry
    return do()
  File "/home/daniel/Documents/CS/Projects/labs-databases-course/main_project/server/venv/lib/python3.10/site-packages/redis/connection.py", line 599, in <lambda>
    lambda: self._connect(), lambda error: self.disconnect(error)
  File "/home/daniel/Documents/CS/Projects/labs-databases-course/main_project/server/venv/lib/python3.10/site-packages/redis/connection.py", line 664, in _connect
    raise err
  File "/home/daniel/Documents/CS/Projects/labs-databases-course/main_project/server/venv/lib/python3.10/site-packages/redis/connection.py", line 652, in _connect
    sock.connect(socket_address)
ConnectionRefusedError: [Errno 111] Connection refused

During handling of the above exception, another exception occurred:

Traceback (most recent call last):
  File "/home/daniel/Documents/CS/Projects/labs-databases-course/main_project/server/venv/lib/python3.10/site-packages/flask/app.py", line 2525, in wsgi_app
    response = self.full_dispatch_request()
  File "/home/daniel/Documents/CS/Projects/labs-databases-course/main_project/server/venv/lib/python3.10/site-packages/flask/app.py", line 1822, in full_dispatch_request
    rv = self.handle_user_exception(e)
  File "/home/daniel/Documents/CS/Projects/labs-databases-course/main_project/server/venv/lib/python3.10/site-packages/flask_cors/extension.py", line 165, in wrapped_function
    return cors_after_request(app.make_response(f(*args, **kwargs)))
  File "/home/daniel/Documents/CS/Projects/labs-databases-course/main_project/server/venv/lib/python3.10/site-packages/flask/app.py", line 1820, in full_dispatch_request
    rv = self.dispatch_request()
  File "/home/daniel/Documents/CS/Projects/labs-databases-course/main_project/server/venv/lib/python3.10/site-packages/flask/app.py", line 1796, in dispatch_request
    return self.ensure_sync(self.view_functions[rule.endpoint])(**view_args)
  File "/home/daniel/Documents/CS/Projects/labs-databases-course/main_project/server/app.py", line 24, in num_visits
    count = get_hit_counts()
  File "/home/daniel/Documents/CS/Projects/labs-databases-course/main_project/server/utils.py", line 13, in get_hit_counts
    raise exc
  File "/home/daniel/Documents/CS/Projects/labs-databases-course/main_project/server/utils.py", line 10, in get_hit_counts
    return cache.incr('hits')
  File "/home/daniel/Documents/CS/Projects/labs-databases-course/main_project/server/venv/lib/python3.10/site-packages/redis/commands/core.py", line 1852, in incrby
    return self.execute_command("INCRBY", name, amount)
  File "/home/daniel/Documents/CS/Projects/labs-databases-course/main_project/server/venv/lib/python3.10/site-packages/redis/client.py", line 1255, in execute_command
    conn = self.connection or pool.get_connection(command_name, **options)
  File "/home/daniel/Documents/CS/Projects/labs-databases-course/main_project/server/venv/lib/python3.10/site-packages/redis/connection.py", line 1389, in get_connection
    connection.connect()
  File "/home/daniel/Documents/CS/Projects/labs-databases-course/main_project/server/venv/lib/python3.10/site-packages/redis/connection.py", line 604, in connect
    raise ConnectionError(self._error_message(e))
redis.exceptions.ConnectionError: Error 111 connecting to 127.0.0.1:6379. Connection refused.
2022-12-14 15:10:45,705 INFO werkzeug Thread-3 (process_request_thread) : 127.0.0.1 - - [14/Dec/2022 15:10:45] "[35m[1mGET /api/v1/num_visits HTTP/1.1[0m" 500 -
2022-12-14 15:10:55,662 INFO app Thread-4 (process_request_thread) : All users were selected from database
2022-12-14 15:10:55,662 INFO werkzeug Thread-4 (process_request_thread) : 127.0.0.1 - - [14/Dec/2022 15:10:55] "GET /api/v1/get_all_people_data HTTP/1.1" 200 -
2022-12-14 15:10:55,684 INFO app Thread-5 (process_request_thread) : All users were selected from database
2022-12-14 15:10:55,685 INFO werkzeug Thread-5 (process_request_thread) : 127.0.0.1 - - [14/Dec/2022 15:10:55] "GET /api/v1/get_all_people_data HTTP/1.1" 200 -
2022-12-14 15:11:16,279 INFO app Thread-6 (process_request_thread) : All users were selected from database
2022-12-14 15:11:16,279 INFO werkzeug Thread-6 (process_request_thread) : 127.0.0.1 - - [14/Dec/2022 15:11:16] "GET /api/v1/get_all_positions HTTP/1.1" 200 -
2022-12-14 15:11:16,283 INFO app Thread-7 (process_request_thread) : All users were selected from database
2022-12-14 15:11:16,283 INFO werkzeug Thread-7 (process_request_thread) : 127.0.0.1 - - [14/Dec/2022 15:11:16] "GET /api/v1/get_all_positions HTTP/1.1" 200 -
2022-12-14 15:11:21,668 INFO app Thread-8 (process_request_thread) : All users were selected from database
2022-12-14 15:11:21,668 INFO werkzeug Thread-8 (process_request_thread) : 127.0.0.1 - - [14/Dec/2022 15:11:21] "GET /api/v1/get_all_people_data HTTP/1.1" 200 -
2022-12-14 15:11:21,687 INFO app Thread-9 (process_request_thread) : All users were selected from database
2022-12-14 15:11:21,688 INFO werkzeug Thread-9 (process_request_thread) : 127.0.0.1 - - [14/Dec/2022 15:11:21] "GET /api/v1/get_all_people_data HTTP/1.1" 200 -
2022-12-14 15:11:28,644 INFO app Thread-10 (process_request_thread) : All users were selected from database
2022-12-14 15:11:28,644 INFO werkzeug Thread-10 (process_request_thread) : 127.0.0.1 - - [14/Dec/2022 15:11:28] "GET /api/v1/get_all_people_data HTTP/1.1" 200 -
2022-12-14 15:11:28,661 INFO app Thread-11 (process_request_thread) : All users were selected from database
2022-12-14 15:11:28,662 INFO werkzeug Thread-11 (process_request_thread) : 127.0.0.1 - - [14/Dec/2022 15:11:28] "GET /api/v1/get_all_people_data HTTP/1.1" 200 -
2022-12-14 15:11:31,805 ERROR app Thread-12 (process_request_thread) : Exception on /api/v1/num_visits [GET]
Traceback (most recent call last):
  File "/home/daniel/Documents/CS/Projects/labs-databases-course/main_project/server/venv/lib/python3.10/site-packages/redis/connection.py", line 598, in connect
    sock = self.retry.call_with_retry(
  File "/home/daniel/Documents/CS/Projects/labs-databases-course/main_project/server/venv/lib/python3.10/site-packages/redis/retry.py", line 46, in call_with_retry
    return do()
  File "/home/daniel/Documents/CS/Projects/labs-databases-course/main_project/server/venv/lib/python3.10/site-packages/redis/connection.py", line 599, in <lambda>
    lambda: self._connect(), lambda error: self.disconnect(error)
  File "/home/daniel/Documents/CS/Projects/labs-databases-course/main_project/server/venv/lib/python3.10/site-packages/redis/connection.py", line 664, in _connect
    raise err
  File "/home/daniel/Documents/CS/Projects/labs-databases-course/main_project/server/venv/lib/python3.10/site-packages/redis/connection.py", line 652, in _connect
    sock.connect(socket_address)
ConnectionRefusedError: [Errno 111] Connection refused

During handling of the above exception, another exception occurred:

Traceback (most recent call last):
  File "/home/daniel/Documents/CS/Projects/labs-databases-course/main_project/server/venv/lib/python3.10/site-packages/flask/app.py", line 2525, in wsgi_app
    response = self.full_dispatch_request()
  File "/home/daniel/Documents/CS/Projects/labs-databases-course/main_project/server/venv/lib/python3.10/site-packages/flask/app.py", line 1822, in full_dispatch_request
    rv = self.handle_user_exception(e)
  File "/home/daniel/Documents/CS/Projects/labs-databases-course/main_project/server/venv/lib/python3.10/site-packages/flask_cors/extension.py", line 165, in wrapped_function
    return cors_after_request(app.make_response(f(*args, **kwargs)))
  File "/home/daniel/Documents/CS/Projects/labs-databases-course/main_project/server/venv/lib/python3.10/site-packages/flask/app.py", line 1820, in full_dispatch_request
    rv = self.dispatch_request()
  File "/home/daniel/Documents/CS/Projects/labs-databases-course/main_project/server/venv/lib/python3.10/site-packages/flask/app.py", line 1796, in dispatch_request
    return self.ensure_sync(self.view_functions[rule.endpoint])(**view_args)
  File "/home/daniel/Documents/CS/Projects/labs-databases-course/main_project/server/app.py", line 24, in num_visits
    count = get_hit_counts()
  File "/home/daniel/Documents/CS/Projects/labs-databases-course/main_project/server/utils.py", line 13, in get_hit_counts
    raise exc
  File "/home/daniel/Documents/CS/Projects/labs-databases-course/main_project/server/utils.py", line 10, in get_hit_counts
    return cache.incr('hits')
  File "/home/daniel/Documents/CS/Projects/labs-databases-course/main_project/server/venv/lib/python3.10/site-packages/redis/commands/core.py", line 1852, in incrby
    return self.execute_command("INCRBY", name, amount)
  File "/home/daniel/Documents/CS/Projects/labs-databases-course/main_project/server/venv/lib/python3.10/site-packages/redis/client.py", line 1255, in execute_command
    conn = self.connection or pool.get_connection(command_name, **options)
  File "/home/daniel/Documents/CS/Projects/labs-databases-course/main_project/server/venv/lib/python3.10/site-packages/redis/connection.py", line 1389, in get_connection
    connection.connect()
  File "/home/daniel/Documents/CS/Projects/labs-databases-course/main_project/server/venv/lib/python3.10/site-packages/redis/connection.py", line 604, in connect
    raise ConnectionError(self._error_message(e))
redis.exceptions.ConnectionError: Error 111 connecting to 127.0.0.1:6379. Connection refused.
2022-12-14 15:11:31,807 INFO werkzeug Thread-12 (process_request_thread) : 127.0.0.1 - - [14/Dec/2022 15:11:31] "[35m[1mGET /api/v1/num_visits HTTP/1.1[0m" 500 -
2022-12-14 15:33:16,959 INFO werkzeug MainThread : [31m[1mWARNING: This is a development server. Do not use it in a production deployment. Use a production WSGI server instead.[0m
 * Running on http://127.0.0.1:5000
2022-12-14 15:33:16,959 INFO werkzeug MainThread : [33mPress CTRL+C to quit[0m
2022-12-14 15:39:39,555 ERROR app Thread-1 (process_request_thread) : Exception on /api/v1/num_visits [GET]
Traceback (most recent call last):
  File "/home/daniel/Documents/CS/Projects/labs-databases-course/main_project/server/venv/lib/python3.10/site-packages/redis/connection.py", line 598, in connect
    sock = self.retry.call_with_retry(
  File "/home/daniel/Documents/CS/Projects/labs-databases-course/main_project/server/venv/lib/python3.10/site-packages/redis/retry.py", line 46, in call_with_retry
    return do()
  File "/home/daniel/Documents/CS/Projects/labs-databases-course/main_project/server/venv/lib/python3.10/site-packages/redis/connection.py", line 599, in <lambda>
    lambda: self._connect(), lambda error: self.disconnect(error)
  File "/home/daniel/Documents/CS/Projects/labs-databases-course/main_project/server/venv/lib/python3.10/site-packages/redis/connection.py", line 664, in _connect
    raise err
  File "/home/daniel/Documents/CS/Projects/labs-databases-course/main_project/server/venv/lib/python3.10/site-packages/redis/connection.py", line 652, in _connect
    sock.connect(socket_address)
ConnectionRefusedError: [Errno 111] Connection refused

During handling of the above exception, another exception occurred:

Traceback (most recent call last):
  File "/home/daniel/Documents/CS/Projects/labs-databases-course/main_project/server/venv/lib/python3.10/site-packages/flask/app.py", line 2525, in wsgi_app
    response = self.full_dispatch_request()
  File "/home/daniel/Documents/CS/Projects/labs-databases-course/main_project/server/venv/lib/python3.10/site-packages/flask/app.py", line 1822, in full_dispatch_request
    rv = self.handle_user_exception(e)
  File "/home/daniel/Documents/CS/Projects/labs-databases-course/main_project/server/venv/lib/python3.10/site-packages/flask_cors/extension.py", line 165, in wrapped_function
    return cors_after_request(app.make_response(f(*args, **kwargs)))
  File "/home/daniel/Documents/CS/Projects/labs-databases-course/main_project/server/venv/lib/python3.10/site-packages/flask/app.py", line 1820, in full_dispatch_request
    rv = self.dispatch_request()
  File "/home/daniel/Documents/CS/Projects/labs-databases-course/main_project/server/venv/lib/python3.10/site-packages/flask/app.py", line 1796, in dispatch_request
    return self.ensure_sync(self.view_functions[rule.endpoint])(**view_args)
  File "/home/daniel/Documents/CS/Projects/labs-databases-course/main_project/server/app.py", line 24, in num_visits
    count = get_hit_counts()
  File "/home/daniel/Documents/CS/Projects/labs-databases-course/main_project/server/utils.py", line 13, in get_hit_counts
    raise exc
  File "/home/daniel/Documents/CS/Projects/labs-databases-course/main_project/server/utils.py", line 10, in get_hit_counts
    return cache.incr('hits')
  File "/home/daniel/Documents/CS/Projects/labs-databases-course/main_project/server/venv/lib/python3.10/site-packages/redis/commands/core.py", line 1852, in incrby
    return self.execute_command("INCRBY", name, amount)
  File "/home/daniel/Documents/CS/Projects/labs-databases-course/main_project/server/venv/lib/python3.10/site-packages/redis/client.py", line 1255, in execute_command
    conn = self.connection or pool.get_connection(command_name, **options)
  File "/home/daniel/Documents/CS/Projects/labs-databases-course/main_project/server/venv/lib/python3.10/site-packages/redis/connection.py", line 1389, in get_connection
    connection.connect()
  File "/home/daniel/Documents/CS/Projects/labs-databases-course/main_project/server/venv/lib/python3.10/site-packages/redis/connection.py", line 604, in connect
    raise ConnectionError(self._error_message(e))
redis.exceptions.ConnectionError: Error 111 connecting to 127.0.0.1:6379. Connection refused.
2022-12-14 15:39:39,569 INFO werkzeug Thread-1 (process_request_thread) : 127.0.0.1 - - [14/Dec/2022 15:39:39] "[35m[1mGET /api/v1/num_visits HTTP/1.1[0m" 500 -
2022-12-14 15:39:40,314 ERROR app Thread-2 (process_request_thread) : Exception on /api/v1/num_visits [GET]
Traceback (most recent call last):
  File "/home/daniel/Documents/CS/Projects/labs-databases-course/main_project/server/venv/lib/python3.10/site-packages/redis/connection.py", line 598, in connect
    sock = self.retry.call_with_retry(
  File "/home/daniel/Documents/CS/Projects/labs-databases-course/main_project/server/venv/lib/python3.10/site-packages/redis/retry.py", line 46, in call_with_retry
    return do()
  File "/home/daniel/Documents/CS/Projects/labs-databases-course/main_project/server/venv/lib/python3.10/site-packages/redis/connection.py", line 599, in <lambda>
    lambda: self._connect(), lambda error: self.disconnect(error)
  File "/home/daniel/Documents/CS/Projects/labs-databases-course/main_project/server/venv/lib/python3.10/site-packages/redis/connection.py", line 664, in _connect
    raise err
  File "/home/daniel/Documents/CS/Projects/labs-databases-course/main_project/server/venv/lib/python3.10/site-packages/redis/connection.py", line 652, in _connect
    sock.connect(socket_address)
ConnectionRefusedError: [Errno 111] Connection refused

During handling of the above exception, another exception occurred:

Traceback (most recent call last):
  File "/home/daniel/Documents/CS/Projects/labs-databases-course/main_project/server/venv/lib/python3.10/site-packages/flask/app.py", line 2525, in wsgi_app
    response = self.full_dispatch_request()
  File "/home/daniel/Documents/CS/Projects/labs-databases-course/main_project/server/venv/lib/python3.10/site-packages/flask/app.py", line 1822, in full_dispatch_request
    rv = self.handle_user_exception(e)
  File "/home/daniel/Documents/CS/Projects/labs-databases-course/main_project/server/venv/lib/python3.10/site-packages/flask_cors/extension.py", line 165, in wrapped_function
    return cors_after_request(app.make_response(f(*args, **kwargs)))
  File "/home/daniel/Documents/CS/Projects/labs-databases-course/main_project/server/venv/lib/python3.10/site-packages/flask/app.py", line 1820, in full_dispatch_request
    rv = self.dispatch_request()
  File "/home/daniel/Documents/CS/Projects/labs-databases-course/main_project/server/venv/lib/python3.10/site-packages/flask/app.py", line 1796, in dispatch_request
    return self.ensure_sync(self.view_functions[rule.endpoint])(**view_args)
  File "/home/daniel/Documents/CS/Projects/labs-databases-course/main_project/server/app.py", line 24, in num_visits
    count = get_hit_counts()
  File "/home/daniel/Documents/CS/Projects/labs-databases-course/main_project/server/utils.py", line 13, in get_hit_counts
    raise exc
  File "/home/daniel/Documents/CS/Projects/labs-databases-course/main_project/server/utils.py", line 10, in get_hit_counts
    return cache.incr('hits')
  File "/home/daniel/Documents/CS/Projects/labs-databases-course/main_project/server/venv/lib/python3.10/site-packages/redis/commands/core.py", line 1852, in incrby
    return self.execute_command("INCRBY", name, amount)
  File "/home/daniel/Documents/CS/Projects/labs-databases-course/main_project/server/venv/lib/python3.10/site-packages/redis/client.py", line 1255, in execute_command
    conn = self.connection or pool.get_connection(command_name, **options)
  File "/home/daniel/Documents/CS/Projects/labs-databases-course/main_project/server/venv/lib/python3.10/site-packages/redis/connection.py", line 1389, in get_connection
    connection.connect()
  File "/home/daniel/Documents/CS/Projects/labs-databases-course/main_project/server/venv/lib/python3.10/site-packages/redis/connection.py", line 604, in connect
    raise ConnectionError(self._error_message(e))
redis.exceptions.ConnectionError: Error 111 connecting to 127.0.0.1:6379. Connection refused.
2022-12-14 15:39:40,317 INFO werkzeug Thread-2 (process_request_thread) : 127.0.0.1 - - [14/Dec/2022 15:39:40] "[35m[1mGET /api/v1/num_visits HTTP/1.1[0m" 500 -
2022-12-14 15:39:41,624 ERROR app Thread-3 (process_request_thread) : Exception on /api/v1/num_visits [GET]
Traceback (most recent call last):
  File "/home/daniel/Documents/CS/Projects/labs-databases-course/main_project/server/venv/lib/python3.10/site-packages/redis/connection.py", line 598, in connect
    sock = self.retry.call_with_retry(
  File "/home/daniel/Documents/CS/Projects/labs-databases-course/main_project/server/venv/lib/python3.10/site-packages/redis/retry.py", line 46, in call_with_retry
    return do()
  File "/home/daniel/Documents/CS/Projects/labs-databases-course/main_project/server/venv/lib/python3.10/site-packages/redis/connection.py", line 599, in <lambda>
    lambda: self._connect(), lambda error: self.disconnect(error)
  File "/home/daniel/Documents/CS/Projects/labs-databases-course/main_project/server/venv/lib/python3.10/site-packages/redis/connection.py", line 664, in _connect
    raise err
  File "/home/daniel/Documents/CS/Projects/labs-databases-course/main_project/server/venv/lib/python3.10/site-packages/redis/connection.py", line 652, in _connect
    sock.connect(socket_address)
ConnectionRefusedError: [Errno 111] Connection refused

During handling of the above exception, another exception occurred:

Traceback (most recent call last):
  File "/home/daniel/Documents/CS/Projects/labs-databases-course/main_project/server/venv/lib/python3.10/site-packages/flask/app.py", line 2525, in wsgi_app
    response = self.full_dispatch_request()
  File "/home/daniel/Documents/CS/Projects/labs-databases-course/main_project/server/venv/lib/python3.10/site-packages/flask/app.py", line 1822, in full_dispatch_request
    rv = self.handle_user_exception(e)
  File "/home/daniel/Documents/CS/Projects/labs-databases-course/main_project/server/venv/lib/python3.10/site-packages/flask_cors/extension.py", line 165, in wrapped_function
    return cors_after_request(app.make_response(f(*args, **kwargs)))
  File "/home/daniel/Documents/CS/Projects/labs-databases-course/main_project/server/venv/lib/python3.10/site-packages/flask/app.py", line 1820, in full_dispatch_request
    rv = self.dispatch_request()
  File "/home/daniel/Documents/CS/Projects/labs-databases-course/main_project/server/venv/lib/python3.10/site-packages/flask/app.py", line 1796, in dispatch_request
    return self.ensure_sync(self.view_functions[rule.endpoint])(**view_args)
  File "/home/daniel/Documents/CS/Projects/labs-databases-course/main_project/server/app.py", line 24, in num_visits
    count = get_hit_counts()
  File "/home/daniel/Documents/CS/Projects/labs-databases-course/main_project/server/utils.py", line 13, in get_hit_counts
    raise exc
  File "/home/daniel/Documents/CS/Projects/labs-databases-course/main_project/server/utils.py", line 10, in get_hit_counts
    return cache.incr('hits')
  File "/home/daniel/Documents/CS/Projects/labs-databases-course/main_project/server/venv/lib/python3.10/site-packages/redis/commands/core.py", line 1852, in incrby
    return self.execute_command("INCRBY", name, amount)
  File "/home/daniel/Documents/CS/Projects/labs-databases-course/main_project/server/venv/lib/python3.10/site-packages/redis/client.py", line 1255, in execute_command
    conn = self.connection or pool.get_connection(command_name, **options)
  File "/home/daniel/Documents/CS/Projects/labs-databases-course/main_project/server/venv/lib/python3.10/site-packages/redis/connection.py", line 1389, in get_connection
    connection.connect()
  File "/home/daniel/Documents/CS/Projects/labs-databases-course/main_project/server/venv/lib/python3.10/site-packages/redis/connection.py", line 604, in connect
    raise ConnectionError(self._error_message(e))
redis.exceptions.ConnectionError: Error 111 connecting to 127.0.0.1:6379. Connection refused.
2022-12-14 15:39:41,626 INFO werkzeug Thread-3 (process_request_thread) : 127.0.0.1 - - [14/Dec/2022 15:39:41] "[35m[1mGET /api/v1/num_visits HTTP/1.1[0m" 500 -
2022-12-14 15:42:50,459 ERROR app Thread-4 (process_request_thread) : Exception on /api/v1/num_visits [GET]
Traceback (most recent call last):
  File "/home/daniel/Documents/CS/Projects/labs-databases-course/main_project/server/venv/lib/python3.10/site-packages/redis/connection.py", line 598, in connect
    sock = self.retry.call_with_retry(
  File "/home/daniel/Documents/CS/Projects/labs-databases-course/main_project/server/venv/lib/python3.10/site-packages/redis/retry.py", line 46, in call_with_retry
    return do()
  File "/home/daniel/Documents/CS/Projects/labs-databases-course/main_project/server/venv/lib/python3.10/site-packages/redis/connection.py", line 599, in <lambda>
    lambda: self._connect(), lambda error: self.disconnect(error)
  File "/home/daniel/Documents/CS/Projects/labs-databases-course/main_project/server/venv/lib/python3.10/site-packages/redis/connection.py", line 664, in _connect
    raise err
  File "/home/daniel/Documents/CS/Projects/labs-databases-course/main_project/server/venv/lib/python3.10/site-packages/redis/connection.py", line 652, in _connect
    sock.connect(socket_address)
ConnectionRefusedError: [Errno 111] Connection refused

During handling of the above exception, another exception occurred:

Traceback (most recent call last):
  File "/home/daniel/Documents/CS/Projects/labs-databases-course/main_project/server/venv/lib/python3.10/site-packages/flask/app.py", line 2525, in wsgi_app
    response = self.full_dispatch_request()
  File "/home/daniel/Documents/CS/Projects/labs-databases-course/main_project/server/venv/lib/python3.10/site-packages/flask/app.py", line 1822, in full_dispatch_request
    rv = self.handle_user_exception(e)
  File "/home/daniel/Documents/CS/Projects/labs-databases-course/main_project/server/venv/lib/python3.10/site-packages/flask_cors/extension.py", line 165, in wrapped_function
    return cors_after_request(app.make_response(f(*args, **kwargs)))
  File "/home/daniel/Documents/CS/Projects/labs-databases-course/main_project/server/venv/lib/python3.10/site-packages/flask/app.py", line 1820, in full_dispatch_request
    rv = self.dispatch_request()
  File "/home/daniel/Documents/CS/Projects/labs-databases-course/main_project/server/venv/lib/python3.10/site-packages/flask/app.py", line 1796, in dispatch_request
    return self.ensure_sync(self.view_functions[rule.endpoint])(**view_args)
  File "/home/daniel/Documents/CS/Projects/labs-databases-course/main_project/server/app.py", line 24, in num_visits
    count = get_hit_counts()
  File "/home/daniel/Documents/CS/Projects/labs-databases-course/main_project/server/utils.py", line 13, in get_hit_counts
    raise exc
  File "/home/daniel/Documents/CS/Projects/labs-databases-course/main_project/server/utils.py", line 10, in get_hit_counts
    return cache.incr('hits')
  File "/home/daniel/Documents/CS/Projects/labs-databases-course/main_project/server/venv/lib/python3.10/site-packages/redis/commands/core.py", line 1852, in incrby
    return self.execute_command("INCRBY", name, amount)
  File "/home/daniel/Documents/CS/Projects/labs-databases-course/main_project/server/venv/lib/python3.10/site-packages/redis/client.py", line 1255, in execute_command
    conn = self.connection or pool.get_connection(command_name, **options)
  File "/home/daniel/Documents/CS/Projects/labs-databases-course/main_project/server/venv/lib/python3.10/site-packages/redis/connection.py", line 1389, in get_connection
    connection.connect()
  File "/home/daniel/Documents/CS/Projects/labs-databases-course/main_project/server/venv/lib/python3.10/site-packages/redis/connection.py", line 604, in connect
    raise ConnectionError(self._error_message(e))
redis.exceptions.ConnectionError: Error 111 connecting to 127.0.0.1:6379. Connection refused.
2022-12-14 15:42:50,461 INFO werkzeug Thread-4 (process_request_thread) : 127.0.0.1 - - [14/Dec/2022 15:42:50] "[35m[1mGET /api/v1/num_visits HTTP/1.1[0m" 500 -
2022-12-14 15:47:27,253 ERROR app Thread-5 (process_request_thread) : Exception on /api/v1/num_visits [GET]
Traceback (most recent call last):
  File "/home/daniel/Documents/CS/Projects/labs-databases-course/main_project/server/venv/lib/python3.10/site-packages/redis/connection.py", line 598, in connect
    sock = self.retry.call_with_retry(
  File "/home/daniel/Documents/CS/Projects/labs-databases-course/main_project/server/venv/lib/python3.10/site-packages/redis/retry.py", line 46, in call_with_retry
    return do()
  File "/home/daniel/Documents/CS/Projects/labs-databases-course/main_project/server/venv/lib/python3.10/site-packages/redis/connection.py", line 599, in <lambda>
    lambda: self._connect(), lambda error: self.disconnect(error)
  File "/home/daniel/Documents/CS/Projects/labs-databases-course/main_project/server/venv/lib/python3.10/site-packages/redis/connection.py", line 664, in _connect
    raise err
  File "/home/daniel/Documents/CS/Projects/labs-databases-course/main_project/server/venv/lib/python3.10/site-packages/redis/connection.py", line 652, in _connect
    sock.connect(socket_address)
ConnectionRefusedError: [Errno 111] Connection refused

During handling of the above exception, another exception occurred:

Traceback (most recent call last):
  File "/home/daniel/Documents/CS/Projects/labs-databases-course/main_project/server/venv/lib/python3.10/site-packages/flask/app.py", line 2525, in wsgi_app
    response = self.full_dispatch_request()
  File "/home/daniel/Documents/CS/Projects/labs-databases-course/main_project/server/venv/lib/python3.10/site-packages/flask/app.py", line 1822, in full_dispatch_request
    rv = self.handle_user_exception(e)
  File "/home/daniel/Documents/CS/Projects/labs-databases-course/main_project/server/venv/lib/python3.10/site-packages/flask_cors/extension.py", line 165, in wrapped_function
    return cors_after_request(app.make_response(f(*args, **kwargs)))
  File "/home/daniel/Documents/CS/Projects/labs-databases-course/main_project/server/venv/lib/python3.10/site-packages/flask/app.py", line 1820, in full_dispatch_request
    rv = self.dispatch_request()
  File "/home/daniel/Documents/CS/Projects/labs-databases-course/main_project/server/venv/lib/python3.10/site-packages/flask/app.py", line 1796, in dispatch_request
    return self.ensure_sync(self.view_functions[rule.endpoint])(**view_args)
  File "/home/daniel/Documents/CS/Projects/labs-databases-course/main_project/server/app.py", line 24, in num_visits
    count = get_hit_counts()
  File "/home/daniel/Documents/CS/Projects/labs-databases-course/main_project/server/utils.py", line 13, in get_hit_counts
    raise exc
  File "/home/daniel/Documents/CS/Projects/labs-databases-course/main_project/server/utils.py", line 10, in get_hit_counts
    return cache.incr('hits')
  File "/home/daniel/Documents/CS/Projects/labs-databases-course/main_project/server/venv/lib/python3.10/site-packages/redis/commands/core.py", line 1852, in incrby
    return self.execute_command("INCRBY", name, amount)
  File "/home/daniel/Documents/CS/Projects/labs-databases-course/main_project/server/venv/lib/python3.10/site-packages/redis/client.py", line 1255, in execute_command
    conn = self.connection or pool.get_connection(command_name, **options)
  File "/home/daniel/Documents/CS/Projects/labs-databases-course/main_project/server/venv/lib/python3.10/site-packages/redis/connection.py", line 1389, in get_connection
    connection.connect()
  File "/home/daniel/Documents/CS/Projects/labs-databases-course/main_project/server/venv/lib/python3.10/site-packages/redis/connection.py", line 604, in connect
    raise ConnectionError(self._error_message(e))
redis.exceptions.ConnectionError: Error 111 connecting to 127.0.0.1:6379. Connection refused.
2022-12-14 15:47:27,256 INFO werkzeug Thread-5 (process_request_thread) : 127.0.0.1 - - [14/Dec/2022 15:47:27] "[35m[1mGET /api/v1/num_visits HTTP/1.1[0m" 500 -
2022-12-14 15:47:34,539 ERROR app Thread-6 (process_request_thread) : Exception on /api/v1/num_visits [GET]
Traceback (most recent call last):
  File "/home/daniel/Documents/CS/Projects/labs-databases-course/main_project/server/venv/lib/python3.10/site-packages/redis/connection.py", line 598, in connect
    sock = self.retry.call_with_retry(
  File "/home/daniel/Documents/CS/Projects/labs-databases-course/main_project/server/venv/lib/python3.10/site-packages/redis/retry.py", line 46, in call_with_retry
    return do()
  File "/home/daniel/Documents/CS/Projects/labs-databases-course/main_project/server/venv/lib/python3.10/site-packages/redis/connection.py", line 599, in <lambda>
    lambda: self._connect(), lambda error: self.disconnect(error)
  File "/home/daniel/Documents/CS/Projects/labs-databases-course/main_project/server/venv/lib/python3.10/site-packages/redis/connection.py", line 664, in _connect
    raise err
  File "/home/daniel/Documents/CS/Projects/labs-databases-course/main_project/server/venv/lib/python3.10/site-packages/redis/connection.py", line 652, in _connect
    sock.connect(socket_address)
ConnectionRefusedError: [Errno 111] Connection refused

During handling of the above exception, another exception occurred:

Traceback (most recent call last):
  File "/home/daniel/Documents/CS/Projects/labs-databases-course/main_project/server/venv/lib/python3.10/site-packages/flask/app.py", line 2525, in wsgi_app
    response = self.full_dispatch_request()
  File "/home/daniel/Documents/CS/Projects/labs-databases-course/main_project/server/venv/lib/python3.10/site-packages/flask/app.py", line 1822, in full_dispatch_request
    rv = self.handle_user_exception(e)
  File "/home/daniel/Documents/CS/Projects/labs-databases-course/main_project/server/venv/lib/python3.10/site-packages/flask_cors/extension.py", line 165, in wrapped_function
    return cors_after_request(app.make_response(f(*args, **kwargs)))
  File "/home/daniel/Documents/CS/Projects/labs-databases-course/main_project/server/venv/lib/python3.10/site-packages/flask/app.py", line 1820, in full_dispatch_request
    rv = self.dispatch_request()
  File "/home/daniel/Documents/CS/Projects/labs-databases-course/main_project/server/venv/lib/python3.10/site-packages/flask/app.py", line 1796, in dispatch_request
    return self.ensure_sync(self.view_functions[rule.endpoint])(**view_args)
  File "/home/daniel/Documents/CS/Projects/labs-databases-course/main_project/server/app.py", line 24, in num_visits
    count = get_hit_counts()
  File "/home/daniel/Documents/CS/Projects/labs-databases-course/main_project/server/utils.py", line 13, in get_hit_counts
    raise exc
  File "/home/daniel/Documents/CS/Projects/labs-databases-course/main_project/server/utils.py", line 10, in get_hit_counts
    return cache.incr('hits')
  File "/home/daniel/Documents/CS/Projects/labs-databases-course/main_project/server/venv/lib/python3.10/site-packages/redis/commands/core.py", line 1852, in incrby
    return self.execute_command("INCRBY", name, amount)
  File "/home/daniel/Documents/CS/Projects/labs-databases-course/main_project/server/venv/lib/python3.10/site-packages/redis/client.py", line 1255, in execute_command
    conn = self.connection or pool.get_connection(command_name, **options)
  File "/home/daniel/Documents/CS/Projects/labs-databases-course/main_project/server/venv/lib/python3.10/site-packages/redis/connection.py", line 1389, in get_connection
    connection.connect()
  File "/home/daniel/Documents/CS/Projects/labs-databases-course/main_project/server/venv/lib/python3.10/site-packages/redis/connection.py", line 604, in connect
    raise ConnectionError(self._error_message(e))
redis.exceptions.ConnectionError: Error 111 connecting to 127.0.0.1:6379. Connection refused.
2022-12-14 15:47:34,540 INFO werkzeug Thread-6 (process_request_thread) : 127.0.0.1 - - [14/Dec/2022 15:47:34] "[35m[1mGET /api/v1/num_visits HTTP/1.1[0m" 500 -
