2022-12-10 00:11:09,358 INFO werkzeug MainThread : [31m[1mWARNING: This is a development server. Do not use it in a production deployment. Use a production WSGI server instead.[0m
 * Running on http://127.0.0.1:5000
2022-12-10 00:11:09,358 INFO werkzeug MainThread : [33mPress CTRL+C to quit[0m
2022-12-10 00:11:15,791 ERROR app Thread-1 (process_request_thread) : Exception on /api/v1/delete_person [DELETE]
Traceback (most recent call last):
  File "C:\Users\ACER\Documents\2022_fall\БД\labs\main_project\server\venv\lib\site-packages\sqlalchemy\orm\attributes.py", line 327, in __getattr__
    return getattr(self.comparator, key)
AttributeError: 'Comparator' object has no attribute 'id'

The above exception was the direct cause of the following exception:

Traceback (most recent call last):
  File "C:\Users\ACER\Documents\2022_fall\БД\labs\main_project\server\venv\lib\site-packages\flask\app.py", line 2525, in wsgi_app
    response = self.full_dispatch_request()
  File "C:\Users\ACER\Documents\2022_fall\БД\labs\main_project\server\venv\lib\site-packages\flask\app.py", line 1822, in full_dispatch_request
    rv = self.handle_user_exception(e)
  File "C:\Users\ACER\Documents\2022_fall\БД\labs\main_project\server\venv\lib\site-packages\flask_cors\extension.py", line 165, in wrapped_function
    return cors_after_request(app.make_response(f(*args, **kwargs)))
  File "C:\Users\ACER\Documents\2022_fall\БД\labs\main_project\server\venv\lib\site-packages\flask\app.py", line 1820, in full_dispatch_request
    rv = self.dispatch_request()
  File "C:\Users\ACER\Documents\2022_fall\БД\labs\main_project\server\venv\lib\site-packages\flask\app.py", line 1796, in dispatch_request
    return self.ensure_sync(self.view_functions[rule.endpoint])(**view_args)
  File "C:\Users\ACER\Documents\2022_fall\БД\labs\main_project\server\app.py", line 82, in delete_person
    res = session.query(Person.phones).filter(Person.phones.id == data["id"]) \
  File "C:\Users\ACER\Documents\2022_fall\БД\labs\main_project\server\venv\lib\site-packages\sqlalchemy\orm\attributes.py", line 329, in __getattr__
    util.raise_(
  File "C:\Users\ACER\Documents\2022_fall\БД\labs\main_project\server\venv\lib\site-packages\sqlalchemy\util\compat.py", line 210, in raise_
    raise exception
AttributeError: Neither 'InstrumentedAttribute' object nor 'Comparator' object associated with Person.phones has an attribute 'id'
2022-12-10 00:11:15,796 INFO werkzeug Thread-1 (process_request_thread) : 127.0.0.1 - - [10/Dec/2022 00:11:15] "[35m[1mDELETE /api/v1/delete_person HTTP/1.1[0m" 500 -
2022-12-10 00:12:56,197 INFO werkzeug MainThread : [31m[1mWARNING: This is a development server. Do not use it in a production deployment. Use a production WSGI server instead.[0m
 * Running on http://127.0.0.1:5000
2022-12-10 00:12:56,197 INFO werkzeug MainThread : [33mPress CTRL+C to quit[0m
2022-12-10 00:13:01,093 INFO werkzeug Thread-1 (process_request_thread) : 127.0.0.1 - - [10/Dec/2022 00:13:01] "DELETE /api/v1/delete_person HTTP/1.1" 200 -
2022-12-10 00:23:52,186 INFO werkzeug MainThread : [31m[1mWARNING: This is a development server. Do not use it in a production deployment. Use a production WSGI server instead.[0m
 * Running on http://127.0.0.1:5000
2022-12-10 00:23:52,187 INFO werkzeug MainThread : [33mPress CTRL+C to quit[0m
2022-12-10 00:24:13,882 INFO werkzeug Thread-1 (process_request_thread) : 127.0.0.1 - - [10/Dec/2022 00:24:13] "DELETE /api/v1/delete_person HTTP/1.1" 200 -
2022-12-10 00:25:07,442 INFO werkzeug MainThread : [31m[1mWARNING: This is a development server. Do not use it in a production deployment. Use a production WSGI server instead.[0m
 * Running on http://127.0.0.1:5000
2022-12-10 00:25:07,442 INFO werkzeug MainThread : [33mPress CTRL+C to quit[0m
2022-12-10 00:25:14,822 INFO werkzeug Thread-1 (process_request_thread) : 127.0.0.1 - - [10/Dec/2022 00:25:14] "DELETE /api/v1/delete_person HTTP/1.1" 200 -
2022-12-10 00:26:05,011 INFO werkzeug MainThread : [31m[1mWARNING: This is a development server. Do not use it in a production deployment. Use a production WSGI server instead.[0m
 * Running on http://127.0.0.1:5000
2022-12-10 00:26:05,012 INFO werkzeug MainThread : [33mPress CTRL+C to quit[0m
2022-12-10 00:26:12,505 INFO werkzeug Thread-1 (process_request_thread) : 127.0.0.1 - - [10/Dec/2022 00:26:12] "DELETE /api/v1/delete_person HTTP/1.1" 200 -
2022-12-10 00:33:57,070 INFO werkzeug MainThread : [31m[1mWARNING: This is a development server. Do not use it in a production deployment. Use a production WSGI server instead.[0m
 * Running on http://127.0.0.1:5000
2022-12-10 00:33:57,071 INFO werkzeug MainThread : [33mPress CTRL+C to quit[0m
2022-12-10 00:34:34,220 ERROR app Thread-1 (process_request_thread) : Exception on /api/v1/num_visits [GET]
Traceback (most recent call last):
  File "C:\Users\ACER\Documents\2022_fall\БД\labs\main_project\server\venv\lib\site-packages\redis\connection.py", line 598, in connect
    sock = self.retry.call_with_retry(
  File "C:\Users\ACER\Documents\2022_fall\БД\labs\main_project\server\venv\lib\site-packages\redis\retry.py", line 46, in call_with_retry
    return do()
  File "C:\Users\ACER\Documents\2022_fall\БД\labs\main_project\server\venv\lib\site-packages\redis\connection.py", line 599, in <lambda>
    lambda: self._connect(), lambda error: self.disconnect(error)
  File "C:\Users\ACER\Documents\2022_fall\БД\labs\main_project\server\venv\lib\site-packages\redis\connection.py", line 664, in _connect
    raise err
  File "C:\Users\ACER\Documents\2022_fall\БД\labs\main_project\server\venv\lib\site-packages\redis\connection.py", line 652, in _connect
    sock.connect(socket_address)
ConnectionRefusedError: [WinError 10061] Подключение не установлено, т.к. конечный компьютер отверг запрос на подключение

During handling of the above exception, another exception occurred:

Traceback (most recent call last):
  File "C:\Users\ACER\Documents\2022_fall\БД\labs\main_project\server\venv\lib\site-packages\flask\app.py", line 2525, in wsgi_app
    response = self.full_dispatch_request()
  File "C:\Users\ACER\Documents\2022_fall\БД\labs\main_project\server\venv\lib\site-packages\flask\app.py", line 1822, in full_dispatch_request
    rv = self.handle_user_exception(e)
  File "C:\Users\ACER\Documents\2022_fall\БД\labs\main_project\server\venv\lib\site-packages\flask_cors\extension.py", line 165, in wrapped_function
    return cors_after_request(app.make_response(f(*args, **kwargs)))
  File "C:\Users\ACER\Documents\2022_fall\БД\labs\main_project\server\venv\lib\site-packages\flask\app.py", line 1820, in full_dispatch_request
    rv = self.dispatch_request()
  File "C:\Users\ACER\Documents\2022_fall\БД\labs\main_project\server\venv\lib\site-packages\flask\app.py", line 1796, in dispatch_request
    return self.ensure_sync(self.view_functions[rule.endpoint])(**view_args)
  File "C:\Users\ACER\Documents\2022_fall\БД\labs\main_project\server\app.py", line 23, in num_visits
    count = get_hit_counts()
  File "C:\Users\ACER\Documents\2022_fall\БД\labs\main_project\server\utils.py", line 12, in get_hit_counts
    raise exc
  File "C:\Users\ACER\Documents\2022_fall\БД\labs\main_project\server\utils.py", line 9, in get_hit_counts
    return cache.incr('hits')
  File "C:\Users\ACER\Documents\2022_fall\БД\labs\main_project\server\venv\lib\site-packages\redis\commands\core.py", line 1852, in incrby
    return self.execute_command("INCRBY", name, amount)
  File "C:\Users\ACER\Documents\2022_fall\БД\labs\main_project\server\venv\lib\site-packages\redis\client.py", line 1255, in execute_command
    conn = self.connection or pool.get_connection(command_name, **options)
  File "C:\Users\ACER\Documents\2022_fall\БД\labs\main_project\server\venv\lib\site-packages\redis\connection.py", line 1389, in get_connection
    connection.connect()
  File "C:\Users\ACER\Documents\2022_fall\БД\labs\main_project\server\venv\lib\site-packages\redis\connection.py", line 604, in connect
    raise ConnectionError(self._error_message(e))
redis.exceptions.ConnectionError: Error 10061 connecting to 127.0.0.1:6379. Подключение не установлено, т.к. конечный компьютер отверг запрос на подключение.
2022-12-10 00:34:34,251 INFO werkzeug Thread-1 (process_request_thread) : 127.0.0.1 - - [10/Dec/2022 00:34:34] "[35m[1mGET /api/v1/num_visits HTTP/1.1[0m" 500 -
2022-12-10 00:34:35,653 INFO app Thread-3 (process_request_thread) : All users were selected from database
2022-12-10 00:34:35,654 INFO werkzeug Thread-3 (process_request_thread) : 127.0.0.1 - - [10/Dec/2022 00:34:35] "GET /api/v1/get_all_people_data HTTP/1.1" 200 -
2022-12-10 00:34:35,676 INFO app Thread-4 (process_request_thread) : All users were selected from database
2022-12-10 00:34:35,677 INFO werkzeug Thread-4 (process_request_thread) : 127.0.0.1 - - [10/Dec/2022 00:34:35] "GET /api/v1/get_all_people_data HTTP/1.1" 200 -
2022-12-10 00:34:49,054 ERROR app Thread-2 (process_request_thread) : Exception on /api/v1/num_visits [GET]
Traceback (most recent call last):
  File "C:\Users\ACER\Documents\2022_fall\БД\labs\main_project\server\venv\lib\site-packages\redis\connection.py", line 598, in connect
    sock = self.retry.call_with_retry(
  File "C:\Users\ACER\Documents\2022_fall\БД\labs\main_project\server\venv\lib\site-packages\redis\retry.py", line 46, in call_with_retry
    return do()
  File "C:\Users\ACER\Documents\2022_fall\БД\labs\main_project\server\venv\lib\site-packages\redis\connection.py", line 599, in <lambda>
    lambda: self._connect(), lambda error: self.disconnect(error)
  File "C:\Users\ACER\Documents\2022_fall\БД\labs\main_project\server\venv\lib\site-packages\redis\connection.py", line 664, in _connect
    raise err
  File "C:\Users\ACER\Documents\2022_fall\БД\labs\main_project\server\venv\lib\site-packages\redis\connection.py", line 652, in _connect
    sock.connect(socket_address)
ConnectionRefusedError: [WinError 10061] Подключение не установлено, т.к. конечный компьютер отверг запрос на подключение

During handling of the above exception, another exception occurred:

Traceback (most recent call last):
  File "C:\Users\ACER\Documents\2022_fall\БД\labs\main_project\server\venv\lib\site-packages\flask\app.py", line 2525, in wsgi_app
    response = self.full_dispatch_request()
  File "C:\Users\ACER\Documents\2022_fall\БД\labs\main_project\server\venv\lib\site-packages\flask\app.py", line 1822, in full_dispatch_request
    rv = self.handle_user_exception(e)
  File "C:\Users\ACER\Documents\2022_fall\БД\labs\main_project\server\venv\lib\site-packages\flask_cors\extension.py", line 165, in wrapped_function
    return cors_after_request(app.make_response(f(*args, **kwargs)))
  File "C:\Users\ACER\Documents\2022_fall\БД\labs\main_project\server\venv\lib\site-packages\flask\app.py", line 1820, in full_dispatch_request
    rv = self.dispatch_request()
  File "C:\Users\ACER\Documents\2022_fall\БД\labs\main_project\server\venv\lib\site-packages\flask\app.py", line 1796, in dispatch_request
    return self.ensure_sync(self.view_functions[rule.endpoint])(**view_args)
  File "C:\Users\ACER\Documents\2022_fall\БД\labs\main_project\server\app.py", line 23, in num_visits
    count = get_hit_counts()
  File "C:\Users\ACER\Documents\2022_fall\БД\labs\main_project\server\utils.py", line 12, in get_hit_counts
    raise exc
  File "C:\Users\ACER\Documents\2022_fall\БД\labs\main_project\server\utils.py", line 9, in get_hit_counts
    return cache.incr('hits')
  File "C:\Users\ACER\Documents\2022_fall\БД\labs\main_project\server\venv\lib\site-packages\redis\commands\core.py", line 1852, in incrby
    return self.execute_command("INCRBY", name, amount)
  File "C:\Users\ACER\Documents\2022_fall\БД\labs\main_project\server\venv\lib\site-packages\redis\client.py", line 1255, in execute_command
    conn = self.connection or pool.get_connection(command_name, **options)
  File "C:\Users\ACER\Documents\2022_fall\БД\labs\main_project\server\venv\lib\site-packages\redis\connection.py", line 1389, in get_connection
    connection.connect()
  File "C:\Users\ACER\Documents\2022_fall\БД\labs\main_project\server\venv\lib\site-packages\redis\connection.py", line 604, in connect
    raise ConnectionError(self._error_message(e))
redis.exceptions.ConnectionError: Error 10061 connecting to 127.0.0.1:6379. Подключение не установлено, т.к. конечный компьютер отверг запрос на подключение.
2022-12-10 00:34:49,054 INFO werkzeug Thread-2 (process_request_thread) : 127.0.0.1 - - [10/Dec/2022 00:34:49] "[35m[1mGET /api/v1/num_visits HTTP/1.1[0m" 500 -
2022-12-10 12:12:49,821 INFO werkzeug MainThread : [31m[1mWARNING: This is a development server. Do not use it in a production deployment. Use a production WSGI server instead.[0m
 * Running on http://127.0.0.1:5000
2022-12-10 12:12:49,821 INFO werkzeug MainThread : [33mPress CTRL+C to quit[0m
2022-12-10 12:14:02,458 INFO werkzeug Thread-1 (process_request_thread) : 127.0.0.1 - - [10/Dec/2022 12:14:02] "POST /api/v1/add_person HTTP/1.1" 200 -
2022-12-10 12:14:38,050 INFO app Thread-2 (process_request_thread) : All users were selected from database
2022-12-10 12:14:38,051 INFO werkzeug Thread-2 (process_request_thread) : 127.0.0.1 - - [10/Dec/2022 12:14:38] "GET /api/v1/get_all_people_data HTTP/1.1" 200 -
2022-12-10 12:14:45,191 INFO werkzeug Thread-3 (process_request_thread) : 127.0.0.1 - - [10/Dec/2022 12:14:45] "DELETE /api/v1/delete_person HTTP/1.1" 200 -
2022-12-10 12:15:55,158 INFO werkzeug Thread-4 (process_request_thread) : 127.0.0.1 - - [10/Dec/2022 12:15:55] "PUT /api/v1/upd_phone HTTP/1.1" 200 -
2022-12-10 12:17:41,162 INFO werkzeug Thread-5 (process_request_thread) : 127.0.0.1 - - [10/Dec/2022 12:17:41] "PUT /api/v1/upd_firstname HTTP/1.1" 200 -
2022-12-10 12:17:56,605 INFO werkzeug Thread-6 (process_request_thread) : 127.0.0.1 - - [10/Dec/2022 12:17:56] "PUT /api/v1/upd_lastname HTTP/1.1" 200 -
2022-12-10 12:18:29,073 INFO werkzeug Thread-7 (process_request_thread) : 127.0.0.1 - - [10/Dec/2022 12:18:29] "PUT /api/v1/upd_position HTTP/1.1" 200 -
2022-12-10 12:24:42,190 INFO werkzeug Thread-8 (process_request_thread) : 127.0.0.1 - - [10/Dec/2022 12:24:42] "POST /api/v1/add_position HTTP/1.1" 200 -
2022-12-10 12:28:54,631 INFO werkzeug MainThread : [31m[1mWARNING: This is a development server. Do not use it in a production deployment. Use a production WSGI server instead.[0m
 * Running on http://127.0.0.1:5000
2022-12-10 12:28:54,631 INFO werkzeug MainThread : [33mPress CTRL+C to quit[0m
2022-12-10 12:28:58,378 INFO werkzeug Thread-1 (process_request_thread) : 127.0.0.1 - - [10/Dec/2022 12:28:58] "DELETE /api/v1/delete_position HTTP/1.1" 200 -
2022-12-10 12:32:20,966 INFO werkzeug MainThread : [31m[1mWARNING: This is a development server. Do not use it in a production deployment. Use a production WSGI server instead.[0m
 * Running on http://127.0.0.1:5000
2022-12-10 12:32:20,966 INFO werkzeug MainThread : [33mPress CTRL+C to quit[0m
2022-12-10 12:32:23,064 INFO app Thread-1 (process_request_thread) : All users were selected from database
2022-12-10 12:32:23,065 INFO werkzeug Thread-1 (process_request_thread) : 127.0.0.1 - - [10/Dec/2022 12:32:23] "GET /api/v1/get_all_positions HTTP/1.1" 200 -
2022-12-10 13:07:01,931 INFO werkzeug MainThread : [31m[1mWARNING: This is a development server. Do not use it in a production deployment. Use a production WSGI server instead.[0m
 * Running on http://127.0.0.1:5000
2022-12-10 13:07:01,931 INFO werkzeug MainThread : [33mPress CTRL+C to quit[0m
2022-12-10 13:08:28,537 INFO werkzeug Thread-1 (process_request_thread) : 127.0.0.1 - - [10/Dec/2022 13:08:28] "PUT /api/v1/upd_position HTTP/1.1" 200 -
2022-12-10 13:22:42,920 INFO werkzeug MainThread : [31m[1mWARNING: This is a development server. Do not use it in a production deployment. Use a production WSGI server instead.[0m
 * Running on http://127.0.0.1:5000
2022-12-10 13:22:42,920 INFO werkzeug MainThread : [33mPress CTRL+C to quit[0m
2022-12-10 13:24:05,279 INFO werkzeug MainThread : [31m[1mWARNING: This is a development server. Do not use it in a production deployment. Use a production WSGI server instead.[0m
 * Running on http://127.0.0.1:5000
2022-12-10 13:24:05,279 INFO werkzeug MainThread : [33mPress CTRL+C to quit[0m
2022-12-10 13:24:31,740 ERROR app Thread-1 (process_request_thread) : Exception on /api/v1/num_visits [GET]
Traceback (most recent call last):
  File "C:\Users\ACER\AppData\Local\Packages\PythonSoftwareFoundation.Python.3.10_qbz5n2kfra8p0\LocalCache\local-packages\Python310\site-packages\redis\connection.py", line 598, in connect
    sock = self.retry.call_with_retry(
  File "C:\Users\ACER\AppData\Local\Packages\PythonSoftwareFoundation.Python.3.10_qbz5n2kfra8p0\LocalCache\local-packages\Python310\site-packages\redis\retry.py", line 46, in call_with_retry
    return do()
  File "C:\Users\ACER\AppData\Local\Packages\PythonSoftwareFoundation.Python.3.10_qbz5n2kfra8p0\LocalCache\local-packages\Python310\site-packages\redis\connection.py", line 599, in <lambda>
    lambda: self._connect(), lambda error: self.disconnect(error)
  File "C:\Users\ACER\AppData\Local\Packages\PythonSoftwareFoundation.Python.3.10_qbz5n2kfra8p0\LocalCache\local-packages\Python310\site-packages\redis\connection.py", line 664, in _connect
    raise err
  File "C:\Users\ACER\AppData\Local\Packages\PythonSoftwareFoundation.Python.3.10_qbz5n2kfra8p0\LocalCache\local-packages\Python310\site-packages\redis\connection.py", line 652, in _connect
    sock.connect(socket_address)
ConnectionRefusedError: [WinError 10061] Подключение не установлено, т.к. конечный компьютер отверг запрос на подключение

During handling of the above exception, another exception occurred:

Traceback (most recent call last):
  File "C:\Users\ACER\AppData\Local\Packages\PythonSoftwareFoundation.Python.3.10_qbz5n2kfra8p0\LocalCache\local-packages\Python310\site-packages\flask\app.py", line 2525, in wsgi_app
    response = self.full_dispatch_request()
  File "C:\Users\ACER\AppData\Local\Packages\PythonSoftwareFoundation.Python.3.10_qbz5n2kfra8p0\LocalCache\local-packages\Python310\site-packages\flask\app.py", line 1822, in full_dispatch_request
    rv = self.handle_user_exception(e)
  File "C:\Users\ACER\AppData\Local\Packages\PythonSoftwareFoundation.Python.3.10_qbz5n2kfra8p0\LocalCache\local-packages\Python310\site-packages\flask_cors\extension.py", line 165, in wrapped_function
    return cors_after_request(app.make_response(f(*args, **kwargs)))
  File "C:\Users\ACER\AppData\Local\Packages\PythonSoftwareFoundation.Python.3.10_qbz5n2kfra8p0\LocalCache\local-packages\Python310\site-packages\flask\app.py", line 1820, in full_dispatch_request
    rv = self.dispatch_request()
  File "C:\Users\ACER\AppData\Local\Packages\PythonSoftwareFoundation.Python.3.10_qbz5n2kfra8p0\LocalCache\local-packages\Python310\site-packages\flask\app.py", line 1796, in dispatch_request
    return self.ensure_sync(self.view_functions[rule.endpoint])(**view_args)
  File "C:\Users\ACER\Documents\2022_fall\БД\labs\main_project\server\app.py", line 23, in num_visits
    count = get_hit_counts()
  File "C:\Users\ACER\Documents\2022_fall\БД\labs\main_project\server\utils.py", line 12, in get_hit_counts
    raise exc
  File "C:\Users\ACER\Documents\2022_fall\БД\labs\main_project\server\utils.py", line 9, in get_hit_counts
    return cache.incr('hits')
  File "C:\Users\ACER\AppData\Local\Packages\PythonSoftwareFoundation.Python.3.10_qbz5n2kfra8p0\LocalCache\local-packages\Python310\site-packages\redis\commands\core.py", line 1852, in incrby
    return self.execute_command("INCRBY", name, amount)
  File "C:\Users\ACER\AppData\Local\Packages\PythonSoftwareFoundation.Python.3.10_qbz5n2kfra8p0\LocalCache\local-packages\Python310\site-packages\redis\client.py", line 1255, in execute_command
    conn = self.connection or pool.get_connection(command_name, **options)
  File "C:\Users\ACER\AppData\Local\Packages\PythonSoftwareFoundation.Python.3.10_qbz5n2kfra8p0\LocalCache\local-packages\Python310\site-packages\redis\connection.py", line 1389, in get_connection
    connection.connect()
  File "C:\Users\ACER\AppData\Local\Packages\PythonSoftwareFoundation.Python.3.10_qbz5n2kfra8p0\LocalCache\local-packages\Python310\site-packages\redis\connection.py", line 604, in connect
    raise ConnectionError(self._error_message(e))
redis.exceptions.ConnectionError: Error 10061 connecting to 127.0.0.1:6379. Подключение не установлено, т.к. конечный компьютер отверг запрос на подключение.
2022-12-10 13:24:31,824 INFO werkzeug Thread-1 (process_request_thread) : 127.0.0.1 - - [10/Dec/2022 13:24:31] "[35m[1mGET /api/v1/num_visits HTTP/1.1[0m" 500 -
2022-12-10 13:24:36,744 INFO app Thread-2 (process_request_thread) : All users were selected from database
2022-12-10 13:24:36,746 INFO werkzeug Thread-2 (process_request_thread) : 127.0.0.1 - - [10/Dec/2022 13:24:36] "GET /api/v1/get_all_people_data HTTP/1.1" 200 -
2022-12-10 13:24:36,824 INFO app Thread-3 (process_request_thread) : All users were selected from database
2022-12-10 13:24:36,826 INFO werkzeug Thread-3 (process_request_thread) : 127.0.0.1 - - [10/Dec/2022 13:24:36] "GET /api/v1/get_all_people_data HTTP/1.1" 200 -
2022-12-10 13:24:43,416 INFO werkzeug Thread-4 (process_request_thread) : 127.0.0.1 - - [10/Dec/2022 13:24:43] "OPTIONS /api/v1/delete_person HTTP/1.1" 200 -
2022-12-10 13:24:43,423 ERROR app Thread-5 (process_request_thread) : Exception on /api/v1/delete_person [DELETE]
Traceback (most recent call last):
  File "C:\Users\ACER\AppData\Local\Packages\PythonSoftwareFoundation.Python.3.10_qbz5n2kfra8p0\LocalCache\local-packages\Python310\site-packages\flask\app.py", line 2525, in wsgi_app
    response = self.full_dispatch_request()
  File "C:\Users\ACER\AppData\Local\Packages\PythonSoftwareFoundation.Python.3.10_qbz5n2kfra8p0\LocalCache\local-packages\Python310\site-packages\flask\app.py", line 1822, in full_dispatch_request
    rv = self.handle_user_exception(e)
  File "C:\Users\ACER\AppData\Local\Packages\PythonSoftwareFoundation.Python.3.10_qbz5n2kfra8p0\LocalCache\local-packages\Python310\site-packages\flask_cors\extension.py", line 165, in wrapped_function
    return cors_after_request(app.make_response(f(*args, **kwargs)))
  File "C:\Users\ACER\AppData\Local\Packages\PythonSoftwareFoundation.Python.3.10_qbz5n2kfra8p0\LocalCache\local-packages\Python310\site-packages\flask\app.py", line 1820, in full_dispatch_request
    rv = self.dispatch_request()
  File "C:\Users\ACER\AppData\Local\Packages\PythonSoftwareFoundation.Python.3.10_qbz5n2kfra8p0\LocalCache\local-packages\Python310\site-packages\flask\app.py", line 1796, in dispatch_request
    return self.ensure_sync(self.view_functions[rule.endpoint])(**view_args)
  File "C:\Users\ACER\Documents\2022_fall\БД\labs\main_project\server\app.py", line 115, in delete_person
    session.query(Person).filter(Person.id == data["id"]).delete()
KeyError: 'id'
2022-12-10 13:24:43,426 INFO werkzeug Thread-5 (process_request_thread) : 127.0.0.1 - - [10/Dec/2022 13:24:43] "[35m[1mDELETE /api/v1/delete_person HTTP/1.1[0m" 500 -
2022-12-10 13:27:24,323 INFO werkzeug MainThread : [31m[1mWARNING: This is a development server. Do not use it in a production deployment. Use a production WSGI server instead.[0m
 * Running on http://127.0.0.1:5000
2022-12-10 13:27:24,324 INFO werkzeug MainThread : [33mPress CTRL+C to quit[0m
2022-12-10 13:27:42,159 INFO werkzeug Thread-1 (process_request_thread) : 127.0.0.1 - - [10/Dec/2022 13:27:42] "DELETE /api/v1/delete_person HTTP/1.1" 200 -
2022-12-10 13:49:30,737 INFO werkzeug MainThread : [31m[1mWARNING: This is a development server. Do not use it in a production deployment. Use a production WSGI server instead.[0m
 * Running on http://127.0.0.1:5000
2022-12-10 13:49:30,737 INFO werkzeug MainThread : [33mPress CTRL+C to quit[0m
2022-12-10 13:50:08,265 ERROR app Thread-1 (process_request_thread) : Exception on /api/v1/num_visits [GET]
Traceback (most recent call last):
  File "C:\Users\ACER\AppData\Local\Packages\PythonSoftwareFoundation.Python.3.10_qbz5n2kfra8p0\LocalCache\local-packages\Python310\site-packages\redis\connection.py", line 598, in connect
    sock = self.retry.call_with_retry(
  File "C:\Users\ACER\AppData\Local\Packages\PythonSoftwareFoundation.Python.3.10_qbz5n2kfra8p0\LocalCache\local-packages\Python310\site-packages\redis\retry.py", line 46, in call_with_retry
    return do()
  File "C:\Users\ACER\AppData\Local\Packages\PythonSoftwareFoundation.Python.3.10_qbz5n2kfra8p0\LocalCache\local-packages\Python310\site-packages\redis\connection.py", line 599, in <lambda>
    lambda: self._connect(), lambda error: self.disconnect(error)
  File "C:\Users\ACER\AppData\Local\Packages\PythonSoftwareFoundation.Python.3.10_qbz5n2kfra8p0\LocalCache\local-packages\Python310\site-packages\redis\connection.py", line 664, in _connect
    raise err
  File "C:\Users\ACER\AppData\Local\Packages\PythonSoftwareFoundation.Python.3.10_qbz5n2kfra8p0\LocalCache\local-packages\Python310\site-packages\redis\connection.py", line 652, in _connect
    sock.connect(socket_address)
ConnectionRefusedError: [WinError 10061] Подключение не установлено, т.к. конечный компьютер отверг запрос на подключение

During handling of the above exception, another exception occurred:

Traceback (most recent call last):
  File "C:\Users\ACER\AppData\Local\Packages\PythonSoftwareFoundation.Python.3.10_qbz5n2kfra8p0\LocalCache\local-packages\Python310\site-packages\flask\app.py", line 2525, in wsgi_app
    response = self.full_dispatch_request()
  File "C:\Users\ACER\AppData\Local\Packages\PythonSoftwareFoundation.Python.3.10_qbz5n2kfra8p0\LocalCache\local-packages\Python310\site-packages\flask\app.py", line 1822, in full_dispatch_request
    rv = self.handle_user_exception(e)
  File "C:\Users\ACER\AppData\Local\Packages\PythonSoftwareFoundation.Python.3.10_qbz5n2kfra8p0\LocalCache\local-packages\Python310\site-packages\flask_cors\extension.py", line 165, in wrapped_function
    return cors_after_request(app.make_response(f(*args, **kwargs)))
  File "C:\Users\ACER\AppData\Local\Packages\PythonSoftwareFoundation.Python.3.10_qbz5n2kfra8p0\LocalCache\local-packages\Python310\site-packages\flask\app.py", line 1820, in full_dispatch_request
    rv = self.dispatch_request()
  File "C:\Users\ACER\AppData\Local\Packages\PythonSoftwareFoundation.Python.3.10_qbz5n2kfra8p0\LocalCache\local-packages\Python310\site-packages\flask\app.py", line 1796, in dispatch_request
    return self.ensure_sync(self.view_functions[rule.endpoint])(**view_args)
  File "C:\Users\ACER\Documents\2022_fall\БД\labs\main_project\server\app.py", line 23, in num_visits
    count = get_hit_counts()
  File "C:\Users\ACER\Documents\2022_fall\БД\labs\main_project\server\utils.py", line 12, in get_hit_counts
    raise exc
  File "C:\Users\ACER\Documents\2022_fall\БД\labs\main_project\server\utils.py", line 9, in get_hit_counts
    return cache.incr('hits')
  File "C:\Users\ACER\AppData\Local\Packages\PythonSoftwareFoundation.Python.3.10_qbz5n2kfra8p0\LocalCache\local-packages\Python310\site-packages\redis\commands\core.py", line 1852, in incrby
    return self.execute_command("INCRBY", name, amount)
  File "C:\Users\ACER\AppData\Local\Packages\PythonSoftwareFoundation.Python.3.10_qbz5n2kfra8p0\LocalCache\local-packages\Python310\site-packages\redis\client.py", line 1255, in execute_command
    conn = self.connection or pool.get_connection(command_name, **options)
  File "C:\Users\ACER\AppData\Local\Packages\PythonSoftwareFoundation.Python.3.10_qbz5n2kfra8p0\LocalCache\local-packages\Python310\site-packages\redis\connection.py", line 1389, in get_connection
    connection.connect()
  File "C:\Users\ACER\AppData\Local\Packages\PythonSoftwareFoundation.Python.3.10_qbz5n2kfra8p0\LocalCache\local-packages\Python310\site-packages\redis\connection.py", line 604, in connect
    raise ConnectionError(self._error_message(e))
redis.exceptions.ConnectionError: Error 10061 connecting to 127.0.0.1:6379. Подключение не установлено, т.к. конечный компьютер отверг запрос на подключение.
2022-12-10 13:50:08,280 INFO werkzeug Thread-1 (process_request_thread) : 127.0.0.1 - - [10/Dec/2022 13:50:08] "[35m[1mGET /api/v1/num_visits HTTP/1.1[0m" 500 -
2022-12-10 13:50:23,012 ERROR app Thread-2 (process_request_thread) : Exception on /api/v1/num_visits [GET]
Traceback (most recent call last):
  File "C:\Users\ACER\AppData\Local\Packages\PythonSoftwareFoundation.Python.3.10_qbz5n2kfra8p0\LocalCache\local-packages\Python310\site-packages\redis\connection.py", line 598, in connect
    sock = self.retry.call_with_retry(
  File "C:\Users\ACER\AppData\Local\Packages\PythonSoftwareFoundation.Python.3.10_qbz5n2kfra8p0\LocalCache\local-packages\Python310\site-packages\redis\retry.py", line 46, in call_with_retry
    return do()
  File "C:\Users\ACER\AppData\Local\Packages\PythonSoftwareFoundation.Python.3.10_qbz5n2kfra8p0\LocalCache\local-packages\Python310\site-packages\redis\connection.py", line 599, in <lambda>
    lambda: self._connect(), lambda error: self.disconnect(error)
  File "C:\Users\ACER\AppData\Local\Packages\PythonSoftwareFoundation.Python.3.10_qbz5n2kfra8p0\LocalCache\local-packages\Python310\site-packages\redis\connection.py", line 664, in _connect
    raise err
  File "C:\Users\ACER\AppData\Local\Packages\PythonSoftwareFoundation.Python.3.10_qbz5n2kfra8p0\LocalCache\local-packages\Python310\site-packages\redis\connection.py", line 652, in _connect
    sock.connect(socket_address)
ConnectionRefusedError: [WinError 10061] Подключение не установлено, т.к. конечный компьютер отверг запрос на подключение

During handling of the above exception, another exception occurred:

Traceback (most recent call last):
  File "C:\Users\ACER\AppData\Local\Packages\PythonSoftwareFoundation.Python.3.10_qbz5n2kfra8p0\LocalCache\local-packages\Python310\site-packages\flask\app.py", line 2525, in wsgi_app
    response = self.full_dispatch_request()
  File "C:\Users\ACER\AppData\Local\Packages\PythonSoftwareFoundation.Python.3.10_qbz5n2kfra8p0\LocalCache\local-packages\Python310\site-packages\flask\app.py", line 1822, in full_dispatch_request
    rv = self.handle_user_exception(e)
  File "C:\Users\ACER\AppData\Local\Packages\PythonSoftwareFoundation.Python.3.10_qbz5n2kfra8p0\LocalCache\local-packages\Python310\site-packages\flask_cors\extension.py", line 165, in wrapped_function
    return cors_after_request(app.make_response(f(*args, **kwargs)))
  File "C:\Users\ACER\AppData\Local\Packages\PythonSoftwareFoundation.Python.3.10_qbz5n2kfra8p0\LocalCache\local-packages\Python310\site-packages\flask\app.py", line 1820, in full_dispatch_request
    rv = self.dispatch_request()
  File "C:\Users\ACER\AppData\Local\Packages\PythonSoftwareFoundation.Python.3.10_qbz5n2kfra8p0\LocalCache\local-packages\Python310\site-packages\flask\app.py", line 1796, in dispatch_request
    return self.ensure_sync(self.view_functions[rule.endpoint])(**view_args)
  File "C:\Users\ACER\Documents\2022_fall\БД\labs\main_project\server\app.py", line 23, in num_visits
    count = get_hit_counts()
  File "C:\Users\ACER\Documents\2022_fall\БД\labs\main_project\server\utils.py", line 12, in get_hit_counts
    raise exc
  File "C:\Users\ACER\Documents\2022_fall\БД\labs\main_project\server\utils.py", line 9, in get_hit_counts
    return cache.incr('hits')
  File "C:\Users\ACER\AppData\Local\Packages\PythonSoftwareFoundation.Python.3.10_qbz5n2kfra8p0\LocalCache\local-packages\Python310\site-packages\redis\commands\core.py", line 1852, in incrby
    return self.execute_command("INCRBY", name, amount)
  File "C:\Users\ACER\AppData\Local\Packages\PythonSoftwareFoundation.Python.3.10_qbz5n2kfra8p0\LocalCache\local-packages\Python310\site-packages\redis\client.py", line 1255, in execute_command
    conn = self.connection or pool.get_connection(command_name, **options)
  File "C:\Users\ACER\AppData\Local\Packages\PythonSoftwareFoundation.Python.3.10_qbz5n2kfra8p0\LocalCache\local-packages\Python310\site-packages\redis\connection.py", line 1389, in get_connection
    connection.connect()
  File "C:\Users\ACER\AppData\Local\Packages\PythonSoftwareFoundation.Python.3.10_qbz5n2kfra8p0\LocalCache\local-packages\Python310\site-packages\redis\connection.py", line 604, in connect
    raise ConnectionError(self._error_message(e))
redis.exceptions.ConnectionError: Error 10061 connecting to 127.0.0.1:6379. Подключение не установлено, т.к. конечный компьютер отверг запрос на подключение.
2022-12-10 13:50:23,014 INFO werkzeug Thread-2 (process_request_thread) : 127.0.0.1 - - [10/Dec/2022 13:50:23] "[35m[1mGET /api/v1/num_visits HTTP/1.1[0m" 500 -
2022-12-10 13:51:41,710 INFO app Thread-3 (process_request_thread) : All users were selected from database
2022-12-10 13:51:41,712 INFO werkzeug Thread-3 (process_request_thread) : 127.0.0.1 - - [10/Dec/2022 13:51:41] "GET /api/v1/get_all_people_data HTTP/1.1" 200 -
2022-12-10 13:51:41,753 INFO app Thread-4 (process_request_thread) : All users were selected from database
2022-12-10 13:51:41,753 INFO werkzeug Thread-4 (process_request_thread) : 127.0.0.1 - - [10/Dec/2022 13:51:41] "GET /api/v1/get_all_people_data HTTP/1.1" 200 -
2022-12-10 13:52:35,572 INFO app Thread-5 (process_request_thread) : All users were selected from database
2022-12-10 13:52:35,573 INFO werkzeug Thread-5 (process_request_thread) : 127.0.0.1 - - [10/Dec/2022 13:52:35] "GET /api/v1/get_all_people_data HTTP/1.1" 200 -
2022-12-10 13:52:36,594 INFO app Thread-6 (process_request_thread) : All users were selected from database
2022-12-10 13:52:36,595 INFO werkzeug Thread-6 (process_request_thread) : 127.0.0.1 - - [10/Dec/2022 13:52:36] "GET /api/v1/get_all_people_data HTTP/1.1" 200 -
2022-12-10 13:52:43,590 INFO app Thread-7 (process_request_thread) : All users were selected from database
2022-12-10 13:52:43,591 INFO werkzeug Thread-7 (process_request_thread) : 127.0.0.1 - - [10/Dec/2022 13:52:43] "GET /api/v1/get_all_people_data HTTP/1.1" 200 -
2022-12-10 13:53:30,553 INFO app Thread-8 (process_request_thread) : All users were selected from database
2022-12-10 13:53:30,554 INFO werkzeug Thread-8 (process_request_thread) : 127.0.0.1 - - [10/Dec/2022 13:53:30] "GET /api/v1/get_all_people_data HTTP/1.1" 200 -
2022-12-10 13:55:25,113 INFO werkzeug MainThread : [31m[1mWARNING: This is a development server. Do not use it in a production deployment. Use a production WSGI server instead.[0m
 * Running on http://127.0.0.1:5000
2022-12-10 13:55:25,114 INFO werkzeug MainThread : [33mPress CTRL+C to quit[0m
2022-12-10 13:55:32,568 INFO app Thread-1 (process_request_thread) : All users were selected from database
2022-12-10 13:55:32,570 INFO werkzeug Thread-1 (process_request_thread) : 127.0.0.1 - - [10/Dec/2022 13:55:32] "GET /api/v1/get_all_people_data HTTP/1.1" 200 -
2022-12-10 13:55:32,601 INFO app Thread-2 (process_request_thread) : All users were selected from database
2022-12-10 13:55:32,601 INFO werkzeug Thread-2 (process_request_thread) : 127.0.0.1 - - [10/Dec/2022 13:55:32] "GET /api/v1/get_all_people_data HTTP/1.1" 200 -
2022-12-10 13:55:35,946 INFO app Thread-3 (process_request_thread) : All users were selected from database
2022-12-10 13:55:35,946 INFO werkzeug Thread-3 (process_request_thread) : 127.0.0.1 - - [10/Dec/2022 13:55:35] "GET /api/v1/get_all_people_data HTTP/1.1" 200 -
2022-12-10 13:55:35,976 INFO app Thread-4 (process_request_thread) : All users were selected from database
2022-12-10 13:55:35,976 INFO werkzeug Thread-4 (process_request_thread) : 127.0.0.1 - - [10/Dec/2022 13:55:35] "GET /api/v1/get_all_people_data HTTP/1.1" 200 -
2022-12-10 13:55:45,910 INFO app Thread-6 (process_request_thread) : All users were selected from database
2022-12-10 13:55:45,910 INFO werkzeug Thread-6 (process_request_thread) : 127.0.0.1 - - [10/Dec/2022 13:55:45] "GET /api/v1/get_all_people_data HTTP/1.1" 200 -
2022-12-10 13:55:45,945 INFO app Thread-7 (process_request_thread) : All users were selected from database
2022-12-10 13:55:45,946 INFO werkzeug Thread-7 (process_request_thread) : 127.0.0.1 - - [10/Dec/2022 13:55:45] "GET /api/v1/get_all_people_data HTTP/1.1" 200 -
2022-12-10 13:55:51,407 INFO app Thread-8 (process_request_thread) : All users were selected from database
2022-12-10 13:55:51,407 INFO werkzeug Thread-8 (process_request_thread) : 127.0.0.1 - - [10/Dec/2022 13:55:51] "GET /api/v1/get_all_people_data HTTP/1.1" 200 -
2022-12-10 13:55:52,719 ERROR app Thread-5 (process_request_thread) : Exception on /api/v1/num_visits [GET]
Traceback (most recent call last):
  File "C:\Users\ACER\Documents\2022_fall\БД\labs\main_project\server\venv\lib\site-packages\redis\connection.py", line 598, in connect
    sock = self.retry.call_with_retry(
  File "C:\Users\ACER\Documents\2022_fall\БД\labs\main_project\server\venv\lib\site-packages\redis\retry.py", line 46, in call_with_retry
    return do()
  File "C:\Users\ACER\Documents\2022_fall\БД\labs\main_project\server\venv\lib\site-packages\redis\connection.py", line 599, in <lambda>
    lambda: self._connect(), lambda error: self.disconnect(error)
  File "C:\Users\ACER\Documents\2022_fall\БД\labs\main_project\server\venv\lib\site-packages\redis\connection.py", line 664, in _connect
    raise err
  File "C:\Users\ACER\Documents\2022_fall\БД\labs\main_project\server\venv\lib\site-packages\redis\connection.py", line 652, in _connect
    sock.connect(socket_address)
ConnectionRefusedError: [WinError 10061] Подключение не установлено, т.к. конечный компьютер отверг запрос на подключение

During handling of the above exception, another exception occurred:

Traceback (most recent call last):
  File "C:\Users\ACER\Documents\2022_fall\БД\labs\main_project\server\venv\lib\site-packages\flask\app.py", line 2525, in wsgi_app
    response = self.full_dispatch_request()
  File "C:\Users\ACER\Documents\2022_fall\БД\labs\main_project\server\venv\lib\site-packages\flask\app.py", line 1822, in full_dispatch_request
    rv = self.handle_user_exception(e)
  File "C:\Users\ACER\Documents\2022_fall\БД\labs\main_project\server\venv\lib\site-packages\flask_cors\extension.py", line 165, in wrapped_function
    return cors_after_request(app.make_response(f(*args, **kwargs)))
  File "C:\Users\ACER\Documents\2022_fall\БД\labs\main_project\server\venv\lib\site-packages\flask\app.py", line 1820, in full_dispatch_request
    rv = self.dispatch_request()
  File "C:\Users\ACER\Documents\2022_fall\БД\labs\main_project\server\venv\lib\site-packages\flask\app.py", line 1796, in dispatch_request
    return self.ensure_sync(self.view_functions[rule.endpoint])(**view_args)
  File "C:\Users\ACER\Documents\2022_fall\БД\labs\main_project\server\app.py", line 23, in num_visits
    count = get_hit_counts()
  File "C:\Users\ACER\Documents\2022_fall\БД\labs\main_project\server\utils.py", line 12, in get_hit_counts
    raise exc
  File "C:\Users\ACER\Documents\2022_fall\БД\labs\main_project\server\utils.py", line 9, in get_hit_counts
    return cache.incr('hits')
  File "C:\Users\ACER\Documents\2022_fall\БД\labs\main_project\server\venv\lib\site-packages\redis\commands\core.py", line 1852, in incrby
    return self.execute_command("INCRBY", name, amount)
  File "C:\Users\ACER\Documents\2022_fall\БД\labs\main_project\server\venv\lib\site-packages\redis\client.py", line 1255, in execute_command
    conn = self.connection or pool.get_connection(command_name, **options)
  File "C:\Users\ACER\Documents\2022_fall\БД\labs\main_project\server\venv\lib\site-packages\redis\connection.py", line 1389, in get_connection
    connection.connect()
  File "C:\Users\ACER\Documents\2022_fall\БД\labs\main_project\server\venv\lib\site-packages\redis\connection.py", line 604, in connect
    raise ConnectionError(self._error_message(e))
redis.exceptions.ConnectionError: Error 10061 connecting to 127.0.0.1:6379. Подключение не установлено, т.к. конечный компьютер отверг запрос на подключение.
2022-12-10 13:55:52,915 INFO werkzeug Thread-5 (process_request_thread) : 127.0.0.1 - - [10/Dec/2022 13:55:52] "[35m[1mGET /api/v1/num_visits HTTP/1.1[0m" 500 -
2022-12-10 13:57:21,921 INFO werkzeug MainThread : [31m[1mWARNING: This is a development server. Do not use it in a production deployment. Use a production WSGI server instead.[0m
 * Running on http://127.0.0.1:5000
2022-12-10 13:57:21,922 INFO werkzeug MainThread : [33mPress CTRL+C to quit[0m
2022-12-10 13:57:26,181 INFO app Thread-1 (process_request_thread) : All users were selected from database
2022-12-10 13:57:26,182 INFO werkzeug Thread-1 (process_request_thread) : 127.0.0.1 - - [10/Dec/2022 13:57:26] "GET /api/v1/get_all_people_data HTTP/1.1" 200 -
2022-12-10 13:59:20,948 INFO werkzeug MainThread : [31m[1mWARNING: This is a development server. Do not use it in a production deployment. Use a production WSGI server instead.[0m
 * Running on http://127.0.0.1:5000
2022-12-10 13:59:20,948 INFO werkzeug MainThread : [33mPress CTRL+C to quit[0m
2022-12-10 13:59:25,921 INFO app Thread-1 (process_request_thread) : All users were selected from database
2022-12-10 13:59:25,922 INFO werkzeug Thread-1 (process_request_thread) : 127.0.0.1 - - [10/Dec/2022 13:59:25] "GET /api/v1/get_all_people_data HTTP/1.1" 200 -
2022-12-10 14:00:16,928 INFO app Thread-2 (process_request_thread) : All users were selected from database
2022-12-10 14:00:16,928 INFO werkzeug Thread-2 (process_request_thread) : 127.0.0.1 - - [10/Dec/2022 14:00:16] "GET /api/v1/get_all_positions HTTP/1.1" 200 -
2022-12-10 14:00:21,205 INFO app Thread-3 (process_request_thread) : All users were selected from database
2022-12-10 14:00:21,206 INFO werkzeug Thread-3 (process_request_thread) : 127.0.0.1 - - [10/Dec/2022 14:00:21] "GET /api/v1/get_all_positions HTTP/1.1" 200 -
2022-12-10 14:00:53,086 INFO werkzeug MainThread : [31m[1mWARNING: This is a development server. Do not use it in a production deployment. Use a production WSGI server instead.[0m
 * Running on http://127.0.0.1:5000
2022-12-10 14:00:53,086 INFO werkzeug MainThread : [33mPress CTRL+C to quit[0m
2022-12-10 14:01:06,002 INFO app Thread-1 (process_request_thread) : All users were selected from database
2022-12-10 14:01:06,004 INFO werkzeug Thread-1 (process_request_thread) : 127.0.0.1 - - [10/Dec/2022 14:01:06] "GET /api/v1/get_all_people_data HTTP/1.1" 200 -
2022-12-10 14:01:34,424 INFO werkzeug MainThread : [31m[1mWARNING: This is a development server. Do not use it in a production deployment. Use a production WSGI server instead.[0m
 * Running on http://127.0.0.1:5000
2022-12-10 14:01:34,424 INFO werkzeug MainThread : [33mPress CTRL+C to quit[0m
2022-12-10 14:01:39,342 INFO app Thread-1 (process_request_thread) : All users were selected from database
2022-12-10 14:01:39,343 INFO werkzeug Thread-1 (process_request_thread) : 127.0.0.1 - - [10/Dec/2022 14:01:39] "GET /api/v1/get_all_people_data HTTP/1.1" 200 -
2022-12-10 14:02:02,025 INFO werkzeug MainThread : [31m[1mWARNING: This is a development server. Do not use it in a production deployment. Use a production WSGI server instead.[0m
 * Running on http://127.0.0.1:5000
2022-12-10 14:02:02,025 INFO werkzeug MainThread : [33mPress CTRL+C to quit[0m
2022-12-10 14:02:13,183 INFO werkzeug MainThread : [31m[1mWARNING: This is a development server. Do not use it in a production deployment. Use a production WSGI server instead.[0m
 * Running on http://127.0.0.1:5000
2022-12-10 14:02:13,183 INFO werkzeug MainThread : [33mPress CTRL+C to quit[0m
2022-12-10 14:02:19,440 INFO app Thread-1 (process_request_thread) : All users were selected from database
2022-12-10 14:02:19,443 INFO werkzeug Thread-1 (process_request_thread) : 127.0.0.1 - - [10/Dec/2022 14:02:19] "GET /api/v1/get_all_people_data HTTP/1.1" 200 -
2022-12-10 14:03:24,881 INFO app Thread-3 (process_request_thread) : All users were selected from database
2022-12-10 14:03:24,883 INFO werkzeug Thread-3 (process_request_thread) : 127.0.0.1 - - [10/Dec/2022 14:03:24] "GET /api/v1/get_all_people_data HTTP/1.1" 200 -
2022-12-10 14:03:24,943 ERROR app Thread-2 (process_request_thread) : Exception on /api/v1/num_visits [GET]
Traceback (most recent call last):
  File "C:\Users\ACER\AppData\Local\Packages\PythonSoftwareFoundation.Python.3.10_qbz5n2kfra8p0\LocalCache\local-packages\Python310\site-packages\redis\connection.py", line 598, in connect
    sock = self.retry.call_with_retry(
  File "C:\Users\ACER\AppData\Local\Packages\PythonSoftwareFoundation.Python.3.10_qbz5n2kfra8p0\LocalCache\local-packages\Python310\site-packages\redis\retry.py", line 46, in call_with_retry
    return do()
  File "C:\Users\ACER\AppData\Local\Packages\PythonSoftwareFoundation.Python.3.10_qbz5n2kfra8p0\LocalCache\local-packages\Python310\site-packages\redis\connection.py", line 599, in <lambda>
    lambda: self._connect(), lambda error: self.disconnect(error)
  File "C:\Users\ACER\AppData\Local\Packages\PythonSoftwareFoundation.Python.3.10_qbz5n2kfra8p0\LocalCache\local-packages\Python310\site-packages\redis\connection.py", line 664, in _connect
    raise err
  File "C:\Users\ACER\AppData\Local\Packages\PythonSoftwareFoundation.Python.3.10_qbz5n2kfra8p0\LocalCache\local-packages\Python310\site-packages\redis\connection.py", line 652, in _connect
    sock.connect(socket_address)
ConnectionRefusedError: [WinError 10061] Подключение не установлено, т.к. конечный компьютер отверг запрос на подключение

During handling of the above exception, another exception occurred:

Traceback (most recent call last):
  File "C:\Users\ACER\AppData\Local\Packages\PythonSoftwareFoundation.Python.3.10_qbz5n2kfra8p0\LocalCache\local-packages\Python310\site-packages\flask\app.py", line 2525, in wsgi_app
    response = self.full_dispatch_request()
  File "C:\Users\ACER\AppData\Local\Packages\PythonSoftwareFoundation.Python.3.10_qbz5n2kfra8p0\LocalCache\local-packages\Python310\site-packages\flask\app.py", line 1822, in full_dispatch_request
    rv = self.handle_user_exception(e)
  File "C:\Users\ACER\AppData\Local\Packages\PythonSoftwareFoundation.Python.3.10_qbz5n2kfra8p0\LocalCache\local-packages\Python310\site-packages\flask_cors\extension.py", line 165, in wrapped_function
    return cors_after_request(app.make_response(f(*args, **kwargs)))
  File "C:\Users\ACER\AppData\Local\Packages\PythonSoftwareFoundation.Python.3.10_qbz5n2kfra8p0\LocalCache\local-packages\Python310\site-packages\flask\app.py", line 1820, in full_dispatch_request
    rv = self.dispatch_request()
  File "C:\Users\ACER\AppData\Local\Packages\PythonSoftwareFoundation.Python.3.10_qbz5n2kfra8p0\LocalCache\local-packages\Python310\site-packages\flask\app.py", line 1796, in dispatch_request
    return self.ensure_sync(self.view_functions[rule.endpoint])(**view_args)
  File "C:\Users\ACER\Documents\2022_fall\БД\labs\main_project\server\app.py", line 23, in num_visits
    count = get_hit_counts()
  File "C:\Users\ACER\Documents\2022_fall\БД\labs\main_project\server\utils.py", line 12, in get_hit_counts
    raise exc
  File "C:\Users\ACER\Documents\2022_fall\БД\labs\main_project\server\utils.py", line 9, in get_hit_counts
    return cache.incr('hits')
  File "C:\Users\ACER\AppData\Local\Packages\PythonSoftwareFoundation.Python.3.10_qbz5n2kfra8p0\LocalCache\local-packages\Python310\site-packages\redis\commands\core.py", line 1852, in incrby
    return self.execute_command("INCRBY", name, amount)
  File "C:\Users\ACER\AppData\Local\Packages\PythonSoftwareFoundation.Python.3.10_qbz5n2kfra8p0\LocalCache\local-packages\Python310\site-packages\redis\client.py", line 1255, in execute_command
    conn = self.connection or pool.get_connection(command_name, **options)
  File "C:\Users\ACER\AppData\Local\Packages\PythonSoftwareFoundation.Python.3.10_qbz5n2kfra8p0\LocalCache\local-packages\Python310\site-packages\redis\connection.py", line 1389, in get_connection
    connection.connect()
  File "C:\Users\ACER\AppData\Local\Packages\PythonSoftwareFoundation.Python.3.10_qbz5n2kfra8p0\LocalCache\local-packages\Python310\site-packages\redis\connection.py", line 604, in connect
    raise ConnectionError(self._error_message(e))
redis.exceptions.ConnectionError: Error 10061 connecting to 127.0.0.1:6379. Подключение не установлено, т.к. конечный компьютер отверг запрос на подключение.
2022-12-10 14:03:24,944 INFO app Thread-4 (process_request_thread) : All users were selected from database
2022-12-10 14:03:24,958 INFO werkzeug Thread-2 (process_request_thread) : 127.0.0.1 - - [10/Dec/2022 14:03:24] "[35m[1mGET /api/v1/num_visits HTTP/1.1[0m" 500 -
2022-12-10 14:03:24,959 INFO werkzeug Thread-4 (process_request_thread) : 127.0.0.1 - - [10/Dec/2022 14:03:24] "GET /api/v1/get_all_people_data HTTP/1.1" 200 -
2022-12-10 14:08:25,531 INFO werkzeug Thread-5 (process_request_thread) : 127.0.0.1 - - [10/Dec/2022 14:08:25] "OPTIONS /api/v1/delete_person HTTP/1.1" 200 -
2022-12-10 14:08:25,549 INFO werkzeug Thread-6 (process_request_thread) : 127.0.0.1 - - [10/Dec/2022 14:08:25] "DELETE /api/v1/delete_person HTTP/1.1" 200 -
2022-12-10 14:08:39,294 INFO app Thread-7 (process_request_thread) : All users were selected from database
2022-12-10 14:08:39,295 INFO werkzeug Thread-7 (process_request_thread) : 127.0.0.1 - - [10/Dec/2022 14:08:39] "GET /api/v1/get_all_people_data HTTP/1.1" 200 -
2022-12-10 14:08:39,325 INFO app Thread-8 (process_request_thread) : All users were selected from database
2022-12-10 14:08:39,326 INFO werkzeug Thread-8 (process_request_thread) : 127.0.0.1 - - [10/Dec/2022 14:08:39] "GET /api/v1/get_all_people_data HTTP/1.1" 200 -
2022-12-10 14:16:36,593 INFO app Thread-9 (process_request_thread) : All users were selected from database
2022-12-10 14:16:36,593 INFO werkzeug Thread-9 (process_request_thread) : 127.0.0.1 - - [10/Dec/2022 14:16:36] "GET /api/v1/get_all_people_data HTTP/1.1" 200 -
2022-12-10 14:16:36,624 INFO app Thread-10 (process_request_thread) : All users were selected from database
2022-12-10 14:16:36,624 INFO werkzeug Thread-10 (process_request_thread) : 127.0.0.1 - - [10/Dec/2022 14:16:36] "GET /api/v1/get_all_people_data HTTP/1.1" 200 -
2022-12-10 14:17:09,614 INFO app Thread-11 (process_request_thread) : All users were selected from database
2022-12-10 14:17:09,616 INFO werkzeug Thread-11 (process_request_thread) : 127.0.0.1 - - [10/Dec/2022 14:17:09] "GET /api/v1/get_all_people_data HTTP/1.1" 200 -
2022-12-10 14:17:44,619 INFO app Thread-12 (process_request_thread) : All users were selected from database
2022-12-10 14:17:44,620 INFO werkzeug Thread-12 (process_request_thread) : 127.0.0.1 - - [10/Dec/2022 14:17:44] "GET /api/v1/get_all_people_data HTTP/1.1" 200 -
2022-12-10 14:17:46,608 INFO app Thread-13 (process_request_thread) : All users were selected from database
2022-12-10 14:17:46,608 INFO werkzeug Thread-13 (process_request_thread) : 127.0.0.1 - - [10/Dec/2022 14:17:46] "GET /api/v1/get_all_people_data HTTP/1.1" 200 -
2022-12-10 14:17:54,612 INFO app Thread-14 (process_request_thread) : All users were selected from database
2022-12-10 14:17:54,613 INFO werkzeug Thread-14 (process_request_thread) : 127.0.0.1 - - [10/Dec/2022 14:17:54] "GET /api/v1/get_all_people_data HTTP/1.1" 200 -
2022-12-10 14:18:07,634 INFO app Thread-15 (process_request_thread) : All users were selected from database
2022-12-10 14:18:07,636 INFO werkzeug Thread-15 (process_request_thread) : 127.0.0.1 - - [10/Dec/2022 14:18:07] "GET /api/v1/get_all_people_data HTTP/1.1" 200 -
2022-12-10 14:18:10,613 INFO app Thread-16 (process_request_thread) : All users were selected from database
2022-12-10 14:18:10,614 INFO werkzeug Thread-16 (process_request_thread) : 127.0.0.1 - - [10/Dec/2022 14:18:10] "GET /api/v1/get_all_people_data HTTP/1.1" 200 -
2022-12-10 14:18:15,633 INFO app Thread-17 (process_request_thread) : All users were selected from database
2022-12-10 14:18:15,635 INFO werkzeug Thread-17 (process_request_thread) : 127.0.0.1 - - [10/Dec/2022 14:18:15] "GET /api/v1/get_all_people_data HTTP/1.1" 200 -
2022-12-10 14:18:15,692 INFO app Thread-18 (process_request_thread) : All users were selected from database
2022-12-10 14:18:15,693 INFO werkzeug Thread-18 (process_request_thread) : 127.0.0.1 - - [10/Dec/2022 14:18:15] "GET /api/v1/get_all_people_data HTTP/1.1" 200 -
2022-12-10 14:18:27,607 INFO app Thread-19 (process_request_thread) : All users were selected from database
2022-12-10 14:18:27,608 INFO werkzeug Thread-19 (process_request_thread) : 127.0.0.1 - - [10/Dec/2022 14:18:27] "GET /api/v1/get_all_people_data HTTP/1.1" 200 -
2022-12-10 14:18:29,614 INFO app Thread-20 (process_request_thread) : All users were selected from database
2022-12-10 14:18:29,616 INFO werkzeug Thread-20 (process_request_thread) : 127.0.0.1 - - [10/Dec/2022 14:18:29] "GET /api/v1/get_all_people_data HTTP/1.1" 200 -
2022-12-10 14:18:35,640 INFO app Thread-21 (process_request_thread) : All users were selected from database
2022-12-10 14:18:35,641 INFO werkzeug Thread-21 (process_request_thread) : 127.0.0.1 - - [10/Dec/2022 14:18:35] "GET /api/v1/get_all_people_data HTTP/1.1" 200 -
2022-12-10 14:18:48,581 INFO app Thread-22 (process_request_thread) : All users were selected from database
2022-12-10 14:18:48,582 INFO werkzeug Thread-22 (process_request_thread) : 127.0.0.1 - - [10/Dec/2022 14:18:48] "GET /api/v1/get_all_people_data HTTP/1.1" 200 -
2022-12-10 14:19:20,886 INFO app Thread-23 (process_request_thread) : All users were selected from database
2022-12-10 14:19:20,886 INFO werkzeug Thread-23 (process_request_thread) : 127.0.0.1 - - [10/Dec/2022 14:19:20] "GET /api/v1/get_all_positions HTTP/1.1" 200 -
2022-12-10 14:20:36,603 INFO app Thread-25 (process_request_thread) : All users were selected from database
2022-12-10 14:20:36,606 INFO werkzeug Thread-25 (process_request_thread) : 127.0.0.1 - - [10/Dec/2022 14:20:36] "GET /api/v1/get_all_positions HTTP/1.1" 200 -
2022-12-10 14:20:55,884 INFO app Thread-26 (process_request_thread) : All users were selected from database
2022-12-10 14:20:55,885 INFO werkzeug Thread-26 (process_request_thread) : 127.0.0.1 - - [10/Dec/2022 14:20:55] "GET /api/v1/get_all_positions HTTP/1.1" 200 -
2022-12-10 14:22:10,889 INFO app Thread-28 (process_request_thread) : All users were selected from database
2022-12-10 14:22:10,890 INFO werkzeug Thread-28 (process_request_thread) : 127.0.0.1 - - [10/Dec/2022 14:22:10] "GET /api/v1/get_all_positions HTTP/1.1" 200 -
2022-12-10 14:22:11,564 INFO app Thread-29 (process_request_thread) : All users were selected from database
2022-12-10 14:22:11,566 INFO werkzeug Thread-29 (process_request_thread) : 127.0.0.1 - - [10/Dec/2022 14:22:11] "GET /api/v1/get_all_positions HTTP/1.1" 200 -
2022-12-10 14:22:39,876 INFO app Thread-30 (process_request_thread) : All users were selected from database
2022-12-10 14:22:39,877 INFO werkzeug Thread-30 (process_request_thread) : 127.0.0.1 - - [10/Dec/2022 14:22:39] "GET /api/v1/get_all_positions HTTP/1.1" 200 -
2022-12-10 14:22:58,567 INFO app Thread-31 (process_request_thread) : All users were selected from database
2022-12-10 14:22:58,567 INFO werkzeug Thread-31 (process_request_thread) : 127.0.0.1 - - [10/Dec/2022 14:22:58] "GET /api/v1/get_all_positions HTTP/1.1" 200 -
2022-12-10 14:23:07,907 INFO app Thread-32 (process_request_thread) : All users were selected from database
2022-12-10 14:23:07,911 INFO werkzeug Thread-32 (process_request_thread) : 127.0.0.1 - - [10/Dec/2022 14:23:07] "GET /api/v1/get_all_positions HTTP/1.1" 200 -
2022-12-10 14:23:08,570 INFO app Thread-33 (process_request_thread) : All users were selected from database
2022-12-10 14:23:08,570 INFO werkzeug Thread-33 (process_request_thread) : 127.0.0.1 - - [10/Dec/2022 14:23:08] "GET /api/v1/get_all_positions HTTP/1.1" 200 -
2022-12-10 14:23:13,890 INFO app Thread-34 (process_request_thread) : All users were selected from database
2022-12-10 14:23:13,891 INFO werkzeug Thread-34 (process_request_thread) : 127.0.0.1 - - [10/Dec/2022 14:23:13] "GET /api/v1/get_all_positions HTTP/1.1" 200 -
2022-12-10 14:23:22,576 INFO app Thread-35 (process_request_thread) : All users were selected from database
2022-12-10 14:23:22,579 INFO werkzeug Thread-35 (process_request_thread) : 127.0.0.1 - - [10/Dec/2022 14:23:22] "GET /api/v1/get_all_positions HTTP/1.1" 200 -
2022-12-10 14:23:25,884 INFO app Thread-36 (process_request_thread) : All users were selected from database
2022-12-10 14:23:25,886 INFO werkzeug Thread-36 (process_request_thread) : 127.0.0.1 - - [10/Dec/2022 14:23:25] "GET /api/v1/get_all_positions HTTP/1.1" 200 -
2022-12-10 14:23:38,583 INFO app Thread-37 (process_request_thread) : All users were selected from database
2022-12-10 14:23:38,585 INFO werkzeug Thread-37 (process_request_thread) : 127.0.0.1 - - [10/Dec/2022 14:23:38] "GET /api/v1/get_all_positions HTTP/1.1" 200 -
2022-12-10 14:25:06,238 INFO app Thread-38 (process_request_thread) : All users were selected from database
2022-12-10 14:25:06,239 INFO werkzeug Thread-38 (process_request_thread) : 127.0.0.1 - - [10/Dec/2022 14:25:06] "GET /api/v1/get_all_people_data HTTP/1.1" 200 -
2022-12-10 14:25:06,264 INFO app Thread-39 (process_request_thread) : All users were selected from database
2022-12-10 14:25:06,264 INFO werkzeug Thread-39 (process_request_thread) : 127.0.0.1 - - [10/Dec/2022 14:25:06] "GET /api/v1/get_all_people_data HTTP/1.1" 200 -
2022-12-10 14:29:35,357 INFO app Thread-40 (process_request_thread) : All users were selected from database
2022-12-10 14:29:35,357 INFO werkzeug Thread-40 (process_request_thread) : 127.0.0.1 - - [10/Dec/2022 14:29:35] "GET /api/v1/get_all_positions HTTP/1.1" 200 -
2022-12-10 14:29:35,606 INFO app Thread-41 (process_request_thread) : All users were selected from database
2022-12-10 14:29:35,606 INFO werkzeug Thread-41 (process_request_thread) : 127.0.0.1 - - [10/Dec/2022 14:29:35] "GET /api/v1/get_all_positions HTTP/1.1" 200 -
2022-12-10 14:30:30,617 ERROR app Thread-43 (process_request_thread) : Exception on /api/v1/num_visits [GET]
Traceback (most recent call last):
  File "C:\Users\ACER\AppData\Local\Packages\PythonSoftwareFoundation.Python.3.10_qbz5n2kfra8p0\LocalCache\local-packages\Python310\site-packages\redis\connection.py", line 598, in connect
    sock = self.retry.call_with_retry(
  File "C:\Users\ACER\AppData\Local\Packages\PythonSoftwareFoundation.Python.3.10_qbz5n2kfra8p0\LocalCache\local-packages\Python310\site-packages\redis\retry.py", line 46, in call_with_retry
    return do()
  File "C:\Users\ACER\AppData\Local\Packages\PythonSoftwareFoundation.Python.3.10_qbz5n2kfra8p0\LocalCache\local-packages\Python310\site-packages\redis\connection.py", line 599, in <lambda>
    lambda: self._connect(), lambda error: self.disconnect(error)
  File "C:\Users\ACER\AppData\Local\Packages\PythonSoftwareFoundation.Python.3.10_qbz5n2kfra8p0\LocalCache\local-packages\Python310\site-packages\redis\connection.py", line 664, in _connect
    raise err
  File "C:\Users\ACER\AppData\Local\Packages\PythonSoftwareFoundation.Python.3.10_qbz5n2kfra8p0\LocalCache\local-packages\Python310\site-packages\redis\connection.py", line 652, in _connect
    sock.connect(socket_address)
ConnectionRefusedError: [WinError 10061] Подключение не установлено, т.к. конечный компьютер отверг запрос на подключение

During handling of the above exception, another exception occurred:

Traceback (most recent call last):
  File "C:\Users\ACER\AppData\Local\Packages\PythonSoftwareFoundation.Python.3.10_qbz5n2kfra8p0\LocalCache\local-packages\Python310\site-packages\flask\app.py", line 2525, in wsgi_app
    response = self.full_dispatch_request()
  File "C:\Users\ACER\AppData\Local\Packages\PythonSoftwareFoundation.Python.3.10_qbz5n2kfra8p0\LocalCache\local-packages\Python310\site-packages\flask\app.py", line 1822, in full_dispatch_request
    rv = self.handle_user_exception(e)
  File "C:\Users\ACER\AppData\Local\Packages\PythonSoftwareFoundation.Python.3.10_qbz5n2kfra8p0\LocalCache\local-packages\Python310\site-packages\flask_cors\extension.py", line 165, in wrapped_function
    return cors_after_request(app.make_response(f(*args, **kwargs)))
  File "C:\Users\ACER\AppData\Local\Packages\PythonSoftwareFoundation.Python.3.10_qbz5n2kfra8p0\LocalCache\local-packages\Python310\site-packages\flask\app.py", line 1820, in full_dispatch_request
    rv = self.dispatch_request()
  File "C:\Users\ACER\AppData\Local\Packages\PythonSoftwareFoundation.Python.3.10_qbz5n2kfra8p0\LocalCache\local-packages\Python310\site-packages\flask\app.py", line 1796, in dispatch_request
    return self.ensure_sync(self.view_functions[rule.endpoint])(**view_args)
  File "C:\Users\ACER\Documents\2022_fall\БД\labs\main_project\server\app.py", line 23, in num_visits
    count = get_hit_counts()
  File "C:\Users\ACER\Documents\2022_fall\БД\labs\main_project\server\utils.py", line 12, in get_hit_counts
    raise exc
  File "C:\Users\ACER\Documents\2022_fall\БД\labs\main_project\server\utils.py", line 9, in get_hit_counts
    return cache.incr('hits')
  File "C:\Users\ACER\AppData\Local\Packages\PythonSoftwareFoundation.Python.3.10_qbz5n2kfra8p0\LocalCache\local-packages\Python310\site-packages\redis\commands\core.py", line 1852, in incrby
    return self.execute_command("INCRBY", name, amount)
  File "C:\Users\ACER\AppData\Local\Packages\PythonSoftwareFoundation.Python.3.10_qbz5n2kfra8p0\LocalCache\local-packages\Python310\site-packages\redis\client.py", line 1255, in execute_command
    conn = self.connection or pool.get_connection(command_name, **options)
  File "C:\Users\ACER\AppData\Local\Packages\PythonSoftwareFoundation.Python.3.10_qbz5n2kfra8p0\LocalCache\local-packages\Python310\site-packages\redis\connection.py", line 1389, in get_connection
    connection.connect()
  File "C:\Users\ACER\AppData\Local\Packages\PythonSoftwareFoundation.Python.3.10_qbz5n2kfra8p0\LocalCache\local-packages\Python310\site-packages\redis\connection.py", line 604, in connect
    raise ConnectionError(self._error_message(e))
redis.exceptions.ConnectionError: Error 10061 connecting to 127.0.0.1:6379. Подключение не установлено, т.к. конечный компьютер отверг запрос на подключение.
2022-12-10 14:30:30,618 INFO werkzeug Thread-43 (process_request_thread) : 127.0.0.1 - - [10/Dec/2022 14:30:30] "[35m[1mGET /api/v1/num_visits HTTP/1.1[0m" 500 -
2022-12-10 14:30:45,369 ERROR app Thread-44 (process_request_thread) : Exception on /api/v1/num_visits [GET]
Traceback (most recent call last):
  File "C:\Users\ACER\AppData\Local\Packages\PythonSoftwareFoundation.Python.3.10_qbz5n2kfra8p0\LocalCache\local-packages\Python310\site-packages\redis\connection.py", line 598, in connect
    sock = self.retry.call_with_retry(
  File "C:\Users\ACER\AppData\Local\Packages\PythonSoftwareFoundation.Python.3.10_qbz5n2kfra8p0\LocalCache\local-packages\Python310\site-packages\redis\retry.py", line 46, in call_with_retry
    return do()
  File "C:\Users\ACER\AppData\Local\Packages\PythonSoftwareFoundation.Python.3.10_qbz5n2kfra8p0\LocalCache\local-packages\Python310\site-packages\redis\connection.py", line 599, in <lambda>
    lambda: self._connect(), lambda error: self.disconnect(error)
  File "C:\Users\ACER\AppData\Local\Packages\PythonSoftwareFoundation.Python.3.10_qbz5n2kfra8p0\LocalCache\local-packages\Python310\site-packages\redis\connection.py", line 664, in _connect
    raise err
  File "C:\Users\ACER\AppData\Local\Packages\PythonSoftwareFoundation.Python.3.10_qbz5n2kfra8p0\LocalCache\local-packages\Python310\site-packages\redis\connection.py", line 652, in _connect
    sock.connect(socket_address)
ConnectionRefusedError: [WinError 10061] Подключение не установлено, т.к. конечный компьютер отверг запрос на подключение

During handling of the above exception, another exception occurred:

Traceback (most recent call last):
  File "C:\Users\ACER\AppData\Local\Packages\PythonSoftwareFoundation.Python.3.10_qbz5n2kfra8p0\LocalCache\local-packages\Python310\site-packages\flask\app.py", line 2525, in wsgi_app
    response = self.full_dispatch_request()
  File "C:\Users\ACER\AppData\Local\Packages\PythonSoftwareFoundation.Python.3.10_qbz5n2kfra8p0\LocalCache\local-packages\Python310\site-packages\flask\app.py", line 1822, in full_dispatch_request
    rv = self.handle_user_exception(e)
  File "C:\Users\ACER\AppData\Local\Packages\PythonSoftwareFoundation.Python.3.10_qbz5n2kfra8p0\LocalCache\local-packages\Python310\site-packages\flask_cors\extension.py", line 165, in wrapped_function
    return cors_after_request(app.make_response(f(*args, **kwargs)))
  File "C:\Users\ACER\AppData\Local\Packages\PythonSoftwareFoundation.Python.3.10_qbz5n2kfra8p0\LocalCache\local-packages\Python310\site-packages\flask\app.py", line 1820, in full_dispatch_request
    rv = self.dispatch_request()
  File "C:\Users\ACER\AppData\Local\Packages\PythonSoftwareFoundation.Python.3.10_qbz5n2kfra8p0\LocalCache\local-packages\Python310\site-packages\flask\app.py", line 1796, in dispatch_request
    return self.ensure_sync(self.view_functions[rule.endpoint])(**view_args)
  File "C:\Users\ACER\Documents\2022_fall\БД\labs\main_project\server\app.py", line 23, in num_visits
    count = get_hit_counts()
  File "C:\Users\ACER\Documents\2022_fall\БД\labs\main_project\server\utils.py", line 12, in get_hit_counts
    raise exc
  File "C:\Users\ACER\Documents\2022_fall\БД\labs\main_project\server\utils.py", line 9, in get_hit_counts
    return cache.incr('hits')
  File "C:\Users\ACER\AppData\Local\Packages\PythonSoftwareFoundation.Python.3.10_qbz5n2kfra8p0\LocalCache\local-packages\Python310\site-packages\redis\commands\core.py", line 1852, in incrby
    return self.execute_command("INCRBY", name, amount)
  File "C:\Users\ACER\AppData\Local\Packages\PythonSoftwareFoundation.Python.3.10_qbz5n2kfra8p0\LocalCache\local-packages\Python310\site-packages\redis\client.py", line 1255, in execute_command
    conn = self.connection or pool.get_connection(command_name, **options)
  File "C:\Users\ACER\AppData\Local\Packages\PythonSoftwareFoundation.Python.3.10_qbz5n2kfra8p0\LocalCache\local-packages\Python310\site-packages\redis\connection.py", line 1389, in get_connection
    connection.connect()
  File "C:\Users\ACER\AppData\Local\Packages\PythonSoftwareFoundation.Python.3.10_qbz5n2kfra8p0\LocalCache\local-packages\Python310\site-packages\redis\connection.py", line 604, in connect
    raise ConnectionError(self._error_message(e))
redis.exceptions.ConnectionError: Error 10061 connecting to 127.0.0.1:6379. Подключение не установлено, т.к. конечный компьютер отверг запрос на подключение.
2022-12-10 14:30:45,370 INFO werkzeug Thread-44 (process_request_thread) : 127.0.0.1 - - [10/Dec/2022 14:30:45] "[35m[1mGET /api/v1/num_visits HTTP/1.1[0m" 500 -
2022-12-10 14:31:59,300 ERROR app Thread-45 (process_request_thread) : Exception on /api/v1/num_visits [GET]
Traceback (most recent call last):
  File "C:\Users\ACER\AppData\Local\Packages\PythonSoftwareFoundation.Python.3.10_qbz5n2kfra8p0\LocalCache\local-packages\Python310\site-packages\redis\connection.py", line 598, in connect
    sock = self.retry.call_with_retry(
  File "C:\Users\ACER\AppData\Local\Packages\PythonSoftwareFoundation.Python.3.10_qbz5n2kfra8p0\LocalCache\local-packages\Python310\site-packages\redis\retry.py", line 46, in call_with_retry
    return do()
  File "C:\Users\ACER\AppData\Local\Packages\PythonSoftwareFoundation.Python.3.10_qbz5n2kfra8p0\LocalCache\local-packages\Python310\site-packages\redis\connection.py", line 599, in <lambda>
    lambda: self._connect(), lambda error: self.disconnect(error)
  File "C:\Users\ACER\AppData\Local\Packages\PythonSoftwareFoundation.Python.3.10_qbz5n2kfra8p0\LocalCache\local-packages\Python310\site-packages\redis\connection.py", line 664, in _connect
    raise err
  File "C:\Users\ACER\AppData\Local\Packages\PythonSoftwareFoundation.Python.3.10_qbz5n2kfra8p0\LocalCache\local-packages\Python310\site-packages\redis\connection.py", line 652, in _connect
    sock.connect(socket_address)
ConnectionRefusedError: [WinError 10061] Подключение не установлено, т.к. конечный компьютер отверг запрос на подключение

During handling of the above exception, another exception occurred:

Traceback (most recent call last):
  File "C:\Users\ACER\AppData\Local\Packages\PythonSoftwareFoundation.Python.3.10_qbz5n2kfra8p0\LocalCache\local-packages\Python310\site-packages\flask\app.py", line 2525, in wsgi_app
    response = self.full_dispatch_request()
  File "C:\Users\ACER\AppData\Local\Packages\PythonSoftwareFoundation.Python.3.10_qbz5n2kfra8p0\LocalCache\local-packages\Python310\site-packages\flask\app.py", line 1822, in full_dispatch_request
    rv = self.handle_user_exception(e)
  File "C:\Users\ACER\AppData\Local\Packages\PythonSoftwareFoundation.Python.3.10_qbz5n2kfra8p0\LocalCache\local-packages\Python310\site-packages\flask_cors\extension.py", line 165, in wrapped_function
    return cors_after_request(app.make_response(f(*args, **kwargs)))
  File "C:\Users\ACER\AppData\Local\Packages\PythonSoftwareFoundation.Python.3.10_qbz5n2kfra8p0\LocalCache\local-packages\Python310\site-packages\flask\app.py", line 1820, in full_dispatch_request
    rv = self.dispatch_request()
  File "C:\Users\ACER\AppData\Local\Packages\PythonSoftwareFoundation.Python.3.10_qbz5n2kfra8p0\LocalCache\local-packages\Python310\site-packages\flask\app.py", line 1796, in dispatch_request
    return self.ensure_sync(self.view_functions[rule.endpoint])(**view_args)
  File "C:\Users\ACER\Documents\2022_fall\БД\labs\main_project\server\app.py", line 23, in num_visits
    count = get_hit_counts()
  File "C:\Users\ACER\Documents\2022_fall\БД\labs\main_project\server\utils.py", line 12, in get_hit_counts
    raise exc
  File "C:\Users\ACER\Documents\2022_fall\БД\labs\main_project\server\utils.py", line 9, in get_hit_counts
    return cache.incr('hits')
  File "C:\Users\ACER\AppData\Local\Packages\PythonSoftwareFoundation.Python.3.10_qbz5n2kfra8p0\LocalCache\local-packages\Python310\site-packages\redis\commands\core.py", line 1852, in incrby
    return self.execute_command("INCRBY", name, amount)
  File "C:\Users\ACER\AppData\Local\Packages\PythonSoftwareFoundation.Python.3.10_qbz5n2kfra8p0\LocalCache\local-packages\Python310\site-packages\redis\client.py", line 1255, in execute_command
    conn = self.connection or pool.get_connection(command_name, **options)
  File "C:\Users\ACER\AppData\Local\Packages\PythonSoftwareFoundation.Python.3.10_qbz5n2kfra8p0\LocalCache\local-packages\Python310\site-packages\redis\connection.py", line 1389, in get_connection
    connection.connect()
  File "C:\Users\ACER\AppData\Local\Packages\PythonSoftwareFoundation.Python.3.10_qbz5n2kfra8p0\LocalCache\local-packages\Python310\site-packages\redis\connection.py", line 604, in connect
    raise ConnectionError(self._error_message(e))
redis.exceptions.ConnectionError: Error 10061 connecting to 127.0.0.1:6379. Подключение не установлено, т.к. конечный компьютер отверг запрос на подключение.
2022-12-10 14:31:59,303 INFO werkzeug Thread-45 (process_request_thread) : 127.0.0.1 - - [10/Dec/2022 14:31:59] "[35m[1mGET /api/v1/num_visits HTTP/1.1[0m" 500 -
2022-12-10 14:32:14,069 ERROR app Thread-46 (process_request_thread) : Exception on /api/v1/num_visits [GET]
Traceback (most recent call last):
  File "C:\Users\ACER\AppData\Local\Packages\PythonSoftwareFoundation.Python.3.10_qbz5n2kfra8p0\LocalCache\local-packages\Python310\site-packages\redis\connection.py", line 598, in connect
    sock = self.retry.call_with_retry(
  File "C:\Users\ACER\AppData\Local\Packages\PythonSoftwareFoundation.Python.3.10_qbz5n2kfra8p0\LocalCache\local-packages\Python310\site-packages\redis\retry.py", line 46, in call_with_retry
    return do()
  File "C:\Users\ACER\AppData\Local\Packages\PythonSoftwareFoundation.Python.3.10_qbz5n2kfra8p0\LocalCache\local-packages\Python310\site-packages\redis\connection.py", line 599, in <lambda>
    lambda: self._connect(), lambda error: self.disconnect(error)
  File "C:\Users\ACER\AppData\Local\Packages\PythonSoftwareFoundation.Python.3.10_qbz5n2kfra8p0\LocalCache\local-packages\Python310\site-packages\redis\connection.py", line 664, in _connect
    raise err
  File "C:\Users\ACER\AppData\Local\Packages\PythonSoftwareFoundation.Python.3.10_qbz5n2kfra8p0\LocalCache\local-packages\Python310\site-packages\redis\connection.py", line 652, in _connect
    sock.connect(socket_address)
ConnectionRefusedError: [WinError 10061] Подключение не установлено, т.к. конечный компьютер отверг запрос на подключение

During handling of the above exception, another exception occurred:

Traceback (most recent call last):
  File "C:\Users\ACER\AppData\Local\Packages\PythonSoftwareFoundation.Python.3.10_qbz5n2kfra8p0\LocalCache\local-packages\Python310\site-packages\flask\app.py", line 2525, in wsgi_app
    response = self.full_dispatch_request()
  File "C:\Users\ACER\AppData\Local\Packages\PythonSoftwareFoundation.Python.3.10_qbz5n2kfra8p0\LocalCache\local-packages\Python310\site-packages\flask\app.py", line 1822, in full_dispatch_request
    rv = self.handle_user_exception(e)
  File "C:\Users\ACER\AppData\Local\Packages\PythonSoftwareFoundation.Python.3.10_qbz5n2kfra8p0\LocalCache\local-packages\Python310\site-packages\flask_cors\extension.py", line 165, in wrapped_function
    return cors_after_request(app.make_response(f(*args, **kwargs)))
  File "C:\Users\ACER\AppData\Local\Packages\PythonSoftwareFoundation.Python.3.10_qbz5n2kfra8p0\LocalCache\local-packages\Python310\site-packages\flask\app.py", line 1820, in full_dispatch_request
    rv = self.dispatch_request()
  File "C:\Users\ACER\AppData\Local\Packages\PythonSoftwareFoundation.Python.3.10_qbz5n2kfra8p0\LocalCache\local-packages\Python310\site-packages\flask\app.py", line 1796, in dispatch_request
    return self.ensure_sync(self.view_functions[rule.endpoint])(**view_args)
  File "C:\Users\ACER\Documents\2022_fall\БД\labs\main_project\server\app.py", line 23, in num_visits
    count = get_hit_counts()
  File "C:\Users\ACER\Documents\2022_fall\БД\labs\main_project\server\utils.py", line 12, in get_hit_counts
    raise exc
  File "C:\Users\ACER\Documents\2022_fall\БД\labs\main_project\server\utils.py", line 9, in get_hit_counts
    return cache.incr('hits')
  File "C:\Users\ACER\AppData\Local\Packages\PythonSoftwareFoundation.Python.3.10_qbz5n2kfra8p0\LocalCache\local-packages\Python310\site-packages\redis\commands\core.py", line 1852, in incrby
    return self.execute_command("INCRBY", name, amount)
  File "C:\Users\ACER\AppData\Local\Packages\PythonSoftwareFoundation.Python.3.10_qbz5n2kfra8p0\LocalCache\local-packages\Python310\site-packages\redis\client.py", line 1255, in execute_command
    conn = self.connection or pool.get_connection(command_name, **options)
  File "C:\Users\ACER\AppData\Local\Packages\PythonSoftwareFoundation.Python.3.10_qbz5n2kfra8p0\LocalCache\local-packages\Python310\site-packages\redis\connection.py", line 1389, in get_connection
    connection.connect()
  File "C:\Users\ACER\AppData\Local\Packages\PythonSoftwareFoundation.Python.3.10_qbz5n2kfra8p0\LocalCache\local-packages\Python310\site-packages\redis\connection.py", line 604, in connect
    raise ConnectionError(self._error_message(e))
redis.exceptions.ConnectionError: Error 10061 connecting to 127.0.0.1:6379. Подключение не установлено, т.к. конечный компьютер отверг запрос на подключение.
2022-12-10 14:32:14,075 INFO werkzeug Thread-46 (process_request_thread) : 127.0.0.1 - - [10/Dec/2022 14:32:14] "[35m[1mGET /api/v1/num_visits HTTP/1.1[0m" 500 -
2022-12-10 14:34:20,638 INFO app Thread-47 (process_request_thread) : All users were selected from database
2022-12-10 14:34:20,639 INFO werkzeug Thread-47 (process_request_thread) : 127.0.0.1 - - [10/Dec/2022 14:34:20] "GET /api/v1/get_all_positions HTTP/1.1" 200 -
2022-12-10 14:34:20,894 INFO app Thread-48 (process_request_thread) : All users were selected from database
2022-12-10 14:34:20,895 INFO werkzeug Thread-48 (process_request_thread) : 127.0.0.1 - - [10/Dec/2022 14:34:20] "GET /api/v1/get_all_positions HTTP/1.1" 200 -
2022-12-10 14:34:24,707 INFO app Thread-50 (process_request_thread) : All users were selected from database
2022-12-10 14:34:24,708 INFO werkzeug Thread-50 (process_request_thread) : 127.0.0.1 - - [10/Dec/2022 14:34:24] "GET /api/v1/get_all_people_data HTTP/1.1" 200 -
2022-12-10 14:34:24,744 INFO app Thread-51 (process_request_thread) : All users were selected from database
2022-12-10 14:34:24,746 INFO werkzeug Thread-51 (process_request_thread) : 127.0.0.1 - - [10/Dec/2022 14:34:24] "GET /api/v1/get_all_people_data HTTP/1.1" 200 -
2022-12-10 14:46:59,706 INFO app Thread-52 (process_request_thread) : All users were selected from database
2022-12-10 14:46:59,708 INFO werkzeug Thread-52 (process_request_thread) : 127.0.0.1 - - [10/Dec/2022 14:46:59] "GET /api/v1/get_all_people_data HTTP/1.1" 200 -
2022-12-10 14:46:59,774 INFO app Thread-53 (process_request_thread) : All users were selected from database
2022-12-10 14:46:59,777 INFO werkzeug Thread-53 (process_request_thread) : 127.0.0.1 - - [10/Dec/2022 14:46:59] "GET /api/v1/get_all_people_data HTTP/1.1" 200 -
2022-12-10 14:47:03,178 INFO app Thread-54 (process_request_thread) : All users were selected from database
2022-12-10 14:47:03,179 INFO werkzeug Thread-54 (process_request_thread) : 127.0.0.1 - - [10/Dec/2022 14:47:03] "GET /api/v1/get_all_people_data HTTP/1.1" 200 -
2022-12-10 14:47:03,215 INFO app Thread-55 (process_request_thread) : All users were selected from database
2022-12-10 14:47:03,216 INFO werkzeug Thread-55 (process_request_thread) : 127.0.0.1 - - [10/Dec/2022 14:47:03] "GET /api/v1/get_all_people_data HTTP/1.1" 200 -
2022-12-10 14:48:13,459 INFO werkzeug Thread-56 (process_request_thread) : 127.0.0.1 - - [10/Dec/2022 14:48:13] "POST /api/v1/add_person HTTP/1.1" 200 -
2022-12-10 14:49:18,843 INFO werkzeug Thread-57 (process_request_thread) : 127.0.0.1 - - [10/Dec/2022 14:49:18] "OPTIONS /api/v1/upd_firstname HTTP/1.1" 200 -
2022-12-10 14:49:19,110 ERROR app Thread-58 (process_request_thread) : Exception on /api/v1/upd_firstname [PUT]
Traceback (most recent call last):
  File "C:\Users\ACER\AppData\Local\Packages\PythonSoftwareFoundation.Python.3.10_qbz5n2kfra8p0\LocalCache\local-packages\Python310\site-packages\flask\app.py", line 2525, in wsgi_app
    response = self.full_dispatch_request()
  File "C:\Users\ACER\AppData\Local\Packages\PythonSoftwareFoundation.Python.3.10_qbz5n2kfra8p0\LocalCache\local-packages\Python310\site-packages\flask\app.py", line 1822, in full_dispatch_request
    rv = self.handle_user_exception(e)
  File "C:\Users\ACER\AppData\Local\Packages\PythonSoftwareFoundation.Python.3.10_qbz5n2kfra8p0\LocalCache\local-packages\Python310\site-packages\flask_cors\extension.py", line 165, in wrapped_function
    return cors_after_request(app.make_response(f(*args, **kwargs)))
  File "C:\Users\ACER\AppData\Local\Packages\PythonSoftwareFoundation.Python.3.10_qbz5n2kfra8p0\LocalCache\local-packages\Python310\site-packages\flask\app.py", line 1820, in full_dispatch_request
    rv = self.dispatch_request()
  File "C:\Users\ACER\AppData\Local\Packages\PythonSoftwareFoundation.Python.3.10_qbz5n2kfra8p0\LocalCache\local-packages\Python310\site-packages\flask\app.py", line 1796, in dispatch_request
    return self.ensure_sync(self.view_functions[rule.endpoint])(**view_args)
  File "C:\Users\ACER\Documents\2022_fall\БД\labs\main_project\server\app.py", line 151, in upd_firstname
    .filter(Person.id == data["id"])\
KeyError: 'id'
2022-12-10 14:49:19,112 INFO werkzeug Thread-58 (process_request_thread) : 127.0.0.1 - - [10/Dec/2022 14:49:19] "[35m[1mPUT /api/v1/upd_firstname HTTP/1.1[0m" 500 -
2022-12-10 14:51:25,483 INFO werkzeug Thread-60 (process_request_thread) : 127.0.0.1 - - [10/Dec/2022 14:51:25] "OPTIONS /api/v1/add_person HTTP/1.1" 200 -
2022-12-10 14:51:25,723 ERROR app Thread-61 (process_request_thread) : Exception on /api/v1/add_person [POST]
Traceback (most recent call last):
  File "C:\Users\ACER\AppData\Local\Packages\PythonSoftwareFoundation.Python.3.10_qbz5n2kfra8p0\LocalCache\local-packages\Python310\site-packages\flask\app.py", line 2525, in wsgi_app
    response = self.full_dispatch_request()
  File "C:\Users\ACER\AppData\Local\Packages\PythonSoftwareFoundation.Python.3.10_qbz5n2kfra8p0\LocalCache\local-packages\Python310\site-packages\flask\app.py", line 1822, in full_dispatch_request
    rv = self.handle_user_exception(e)
  File "C:\Users\ACER\AppData\Local\Packages\PythonSoftwareFoundation.Python.3.10_qbz5n2kfra8p0\LocalCache\local-packages\Python310\site-packages\flask_cors\extension.py", line 165, in wrapped_function
    return cors_after_request(app.make_response(f(*args, **kwargs)))
  File "C:\Users\ACER\AppData\Local\Packages\PythonSoftwareFoundation.Python.3.10_qbz5n2kfra8p0\LocalCache\local-packages\Python310\site-packages\flask\app.py", line 1820, in full_dispatch_request
    rv = self.dispatch_request()
  File "C:\Users\ACER\AppData\Local\Packages\PythonSoftwareFoundation.Python.3.10_qbz5n2kfra8p0\LocalCache\local-packages\Python310\site-packages\flask\app.py", line 1796, in dispatch_request
    return self.ensure_sync(self.view_functions[rule.endpoint])(**view_args)
  File "C:\Users\ACER\Documents\2022_fall\БД\labs\main_project\server\app.py", line 85, in add_person
    data["position_id"]
KeyError: 'position_id'
2022-12-10 14:51:25,724 INFO werkzeug Thread-61 (process_request_thread) : 127.0.0.1 - - [10/Dec/2022 14:51:25] "[35m[1mPOST /api/v1/add_person HTTP/1.1[0m" 500 -
2022-12-10 14:52:18,282 INFO werkzeug Thread-62 (process_request_thread) : 127.0.0.1 - - [10/Dec/2022 14:52:18] "OPTIONS /api/v1/add_person HTTP/1.1" 200 -
2022-12-10 14:52:18,601 ERROR app Thread-63 (process_request_thread) : Exception on /api/v1/add_person [POST]
Traceback (most recent call last):
  File "C:\Users\ACER\AppData\Local\Packages\PythonSoftwareFoundation.Python.3.10_qbz5n2kfra8p0\LocalCache\local-packages\Python310\site-packages\flask\app.py", line 2525, in wsgi_app
    response = self.full_dispatch_request()
  File "C:\Users\ACER\AppData\Local\Packages\PythonSoftwareFoundation.Python.3.10_qbz5n2kfra8p0\LocalCache\local-packages\Python310\site-packages\flask\app.py", line 1822, in full_dispatch_request
    rv = self.handle_user_exception(e)
  File "C:\Users\ACER\AppData\Local\Packages\PythonSoftwareFoundation.Python.3.10_qbz5n2kfra8p0\LocalCache\local-packages\Python310\site-packages\flask_cors\extension.py", line 165, in wrapped_function
    return cors_after_request(app.make_response(f(*args, **kwargs)))
  File "C:\Users\ACER\AppData\Local\Packages\PythonSoftwareFoundation.Python.3.10_qbz5n2kfra8p0\LocalCache\local-packages\Python310\site-packages\flask\app.py", line 1820, in full_dispatch_request
    rv = self.dispatch_request()
  File "C:\Users\ACER\AppData\Local\Packages\PythonSoftwareFoundation.Python.3.10_qbz5n2kfra8p0\LocalCache\local-packages\Python310\site-packages\flask\app.py", line 1796, in dispatch_request
    return self.ensure_sync(self.view_functions[rule.endpoint])(**view_args)
  File "C:\Users\ACER\Documents\2022_fall\БД\labs\main_project\server\app.py", line 85, in add_person
    data["position_id"]
KeyError: 'position_id'
2022-12-10 14:52:18,602 INFO werkzeug Thread-63 (process_request_thread) : 127.0.0.1 - - [10/Dec/2022 14:52:18] "[35m[1mPOST /api/v1/add_person HTTP/1.1[0m" 500 -
2022-12-10 14:52:24,764 INFO werkzeug Thread-64 (process_request_thread) : 127.0.0.1 - - [10/Dec/2022 14:52:24] "OPTIONS /api/v1/add_person HTTP/1.1" 200 -
2022-12-10 14:52:25,080 ERROR app Thread-65 (process_request_thread) : Exception on /api/v1/add_person [POST]
Traceback (most recent call last):
  File "C:\Users\ACER\AppData\Local\Packages\PythonSoftwareFoundation.Python.3.10_qbz5n2kfra8p0\LocalCache\local-packages\Python310\site-packages\flask\app.py", line 2525, in wsgi_app
    response = self.full_dispatch_request()
  File "C:\Users\ACER\AppData\Local\Packages\PythonSoftwareFoundation.Python.3.10_qbz5n2kfra8p0\LocalCache\local-packages\Python310\site-packages\flask\app.py", line 1822, in full_dispatch_request
    rv = self.handle_user_exception(e)
  File "C:\Users\ACER\AppData\Local\Packages\PythonSoftwareFoundation.Python.3.10_qbz5n2kfra8p0\LocalCache\local-packages\Python310\site-packages\flask_cors\extension.py", line 165, in wrapped_function
    return cors_after_request(app.make_response(f(*args, **kwargs)))
  File "C:\Users\ACER\AppData\Local\Packages\PythonSoftwareFoundation.Python.3.10_qbz5n2kfra8p0\LocalCache\local-packages\Python310\site-packages\flask\app.py", line 1820, in full_dispatch_request
    rv = self.dispatch_request()
  File "C:\Users\ACER\AppData\Local\Packages\PythonSoftwareFoundation.Python.3.10_qbz5n2kfra8p0\LocalCache\local-packages\Python310\site-packages\flask\app.py", line 1796, in dispatch_request
    return self.ensure_sync(self.view_functions[rule.endpoint])(**view_args)
  File "C:\Users\ACER\Documents\2022_fall\БД\labs\main_project\server\app.py", line 85, in add_person
    data["position_id"]
KeyError: 'position_id'
2022-12-10 14:52:25,082 INFO werkzeug Thread-65 (process_request_thread) : 127.0.0.1 - - [10/Dec/2022 14:52:25] "[35m[1mPOST /api/v1/add_person HTTP/1.1[0m" 500 -
2022-12-10 14:53:02,105 INFO werkzeug Thread-66 (process_request_thread) : 127.0.0.1 - - [10/Dec/2022 14:53:02] "OPTIONS /api/v1/add_person HTTP/1.1" 200 -
2022-12-10 14:53:02,444 INFO werkzeug Thread-67 (process_request_thread) : 127.0.0.1 - - [10/Dec/2022 14:53:02] "POST /api/v1/add_person HTTP/1.1" 200 -
2022-12-10 14:53:43,246 INFO app Thread-69 (process_request_thread) : All users were selected from database
2022-12-10 14:53:43,247 INFO werkzeug Thread-69 (process_request_thread) : 127.0.0.1 - - [10/Dec/2022 14:53:43] "GET /api/v1/get_all_people_data HTTP/1.1" 200 -
2022-12-10 14:53:43,277 INFO app Thread-70 (process_request_thread) : All users were selected from database
2022-12-10 14:53:43,277 INFO werkzeug Thread-70 (process_request_thread) : 127.0.0.1 - - [10/Dec/2022 14:53:43] "GET /api/v1/get_all_people_data HTTP/1.1" 200 -
2022-12-10 14:57:32,087 INFO app Thread-71 (process_request_thread) : All users were selected from database
2022-12-10 14:57:32,089 INFO werkzeug Thread-71 (process_request_thread) : 127.0.0.1 - - [10/Dec/2022 14:57:32] "GET /api/v1/get_all_positions HTTP/1.1" 200 -
2022-12-10 14:57:32,324 INFO app Thread-72 (process_request_thread) : All users were selected from database
2022-12-10 14:57:32,324 INFO werkzeug Thread-72 (process_request_thread) : 127.0.0.1 - - [10/Dec/2022 14:57:32] "GET /api/v1/get_all_positions HTTP/1.1" 200 -
2022-12-10 14:58:00,578 INFO werkzeug Thread-73 (process_request_thread) : 127.0.0.1 - - [10/Dec/2022 14:58:00] "OPTIONS /api/v1/add_position HTTP/1.1" 200 -
2022-12-10 14:58:00,909 INFO werkzeug Thread-74 (process_request_thread) : 127.0.0.1 - - [10/Dec/2022 14:58:00] "POST /api/v1/add_position HTTP/1.1" 200 -
2022-12-10 14:58:05,133 INFO app Thread-75 (process_request_thread) : All users were selected from database
2022-12-10 14:58:05,135 INFO werkzeug Thread-75 (process_request_thread) : 127.0.0.1 - - [10/Dec/2022 14:58:05] "GET /api/v1/get_all_positions HTTP/1.1" 200 -
2022-12-10 14:58:05,450 INFO app Thread-76 (process_request_thread) : All users were selected from database
2022-12-10 14:58:05,453 INFO werkzeug Thread-76 (process_request_thread) : 127.0.0.1 - - [10/Dec/2022 14:58:05] "GET /api/v1/get_all_positions HTTP/1.1" 200 -
2022-12-10 14:58:42,741 INFO app Thread-78 (process_request_thread) : All users were selected from database
2022-12-10 14:58:42,741 INFO werkzeug Thread-78 (process_request_thread) : 127.0.0.1 - - [10/Dec/2022 14:58:42] "GET /api/v1/get_all_people_data HTTP/1.1" 200 -
2022-12-10 14:58:42,775 INFO app Thread-79 (process_request_thread) : All users were selected from database
2022-12-10 14:58:42,776 INFO werkzeug Thread-79 (process_request_thread) : 127.0.0.1 - - [10/Dec/2022 14:58:42] "GET /api/v1/get_all_people_data HTTP/1.1" 200 -
